Workbook

Sheet Datos
A1: Matriz de datos (10×10)
A2: i\j | B2: 0 | C2: 1 | D2: 2 | E2: 3 | F2: 4 | G2: 5 | H2: 6 | I2: 7 | J2: 8 | K2: 9
A3: 0 | B3: 132 | C3: 101 | D3: 111 | E3: 109 | F3: 106 | G3: 88 | H3: 39 | I3: 37 | J3: 45 | K3: 48
A4: 1 | B4: 112 | C4: 101 | D4: 104 | E4: 95 | F4: 83 | G4: 76 | H4: 72 | I4: 91 | J4: 41 | K4: 46
A5: 2 | B5: 104 | C5: 123 | D5: 123 | E5: 114 | F5: 90 | G5: 80 | H5: 110 | I5: 131 | J5: 116 | K5: 104
A6: 3 | B6: 124 | C6: 148 | D6: 128 | E6: 116 | F6: 93 | G6: 85 | H6: 128 | I6: 139 | J6: 165 | K6: 145
A7: 4 | B7: 138 | C7: 138 | D7: 94 | E7: 82 | F7: 79 | G7: 89 | H7: 135 | I7: 140 | J7: 129 | K7: 118
A8: 5 | B8: 111 | C8: 100 | D8: 78 | E8: 84 | F8: 101 | G8: 117 | H8: 140 | I8: 141 | J8: 130 | K8: 114
A9: 6 | B9: 72 | C9: 67 | D9: 88 | E9: 109 | F9: 127 | G9: 134 | H9: 126 | I9: 134 | J9: 158 | K9: 128
A10: 7 | B10: 58 | C10: 51 | D10: 90 | E10: 105 | F10: 111 | G10: 115 | H10: 100 | I10: 126 | J10: 135 | K10: 107
A11: 8 | B11: 49 | C11: 70 | D11: 67 | E11: 74 | F11: 99 | G11: 93 | H11: 102 | I11: 152 | J11: 128 | K11: 79
A12: 9 | B12: 82 | C12: 99 | D12: 81 | E12: 62 | F12: 73 | G12: 77 | H12: 99 | I12: 150 | J12: 128 | K12: 96

Sheet Kernels
A1: Kernels 3×3 (pesos editables)
A2: Nota: Puedes editar los pesos en azul para ver cómo cambia la convolución.
B4: Promedio (box blur) | G4: Gaussiano (aprox.)
B5: 1 | C5: 1 | D5: 1 | E5: Factor | F5: N | G5: 1 | H5: 2 | I5: 1 | J5: Factor | K5: N
B6: 1 | C6: 1 | D6: 1 | E6: Normalización | F6: 9 | G6: 2 | H6: 4 | I6: 2 | J6: Normalización | K6: 16
B7: 1 | C7: 1 | D7: 1 | G7: 1 | H7: 2 | I7: 1
B9: Salida típica: (1/N)·sum(k⊙vecindad). | G9: Suavizado con mayor peso al centro.
B12: Sobel X | G12: Sobel Y
B13: -1 | C13: 0 | D13: 1 | G13: -1 | H13: -2 | I13: -1
B14: -2 | C14: 0 | D14: 2 | G14: 0 | H14: 0 | I14: 0
B15: -1 | C15: 0 | D15: 1 | G15: 1 | H15: 2 | I15: 1
B17: Detecta cambios horizontales (bordes verticales). | G17: Detecta cambios verticales (bordes horizontales).
B20: Laplaciano
B21: 0 | C21: 1 | D21: 0
B22: 1 | C22: -4 | D22: 1
B23: 0 | C23: 1 | D23: 0
B25: Realce de bordes (segunda derivada).

Sheet Convolucion
A1: Convolución 3×3 con fórmulas (sin macros)
A2: Las celdas interiores (i=1..8, j=1..8) se calculan con SUMA de 9 términos usando INDEX(). Bordes se dejan en blanco.
A4: Pixel de ejemplo (centro): | B4: i | C4: 5 | D4: j | E4: 5 | F4: (edita i,j para ver el cálculo)
A6: Vecindad 3×3 de Datos | E6: Kernel (elige) | H6: Producto
A7: =INDEX(Datos!$B$3:$K$12,$C$4+0,$E$4+0) -> 79 | B7: =INDEX(Datos!$B$3:$K$12,$C$4+0,$E$4+1) -> 89 | C7: =INDEX(Datos!$B$3:$K$12,$C$4+0,$E$4+2) -> 135 | E7: =Kernels!B5 -> 1 | F7: =Kernels!C5 -> 1 | G7: =Kernels!D5 -> 1 | H7: =A7*E7 -> 79 | I7: =B7*F7 -> 89 | J7: =C7*G7 -> 135
A8: =INDEX(Datos!$B$3:$K$12,$C$4+1,$E$4+0) -> 101 | B8: =INDEX(Datos!$B$3:$K$12,$C$4+1,$E$4+1) -> 117 | C8: =INDEX(Datos!$B$3:$K$12,$C$4+1,$E$4+2) -> 140 | E8: =Kernels!B6 -> 1 | F8: =Kernels!C6 -> 1 | G8: =Kernels!D6 -> 1 | H8: =A8*E8 -> 101 | I8: =B8*F8 -> 117 | J8: =C8*G8 -> 140
A9: =INDEX(Datos!$B$3:$K$12,$C$4+2,$E$4+0) -> 127 | B9: =INDEX(Datos!$B$3:$K$12,$C$4+2,$E$4+1) -> 134 | C9: =INDEX(Datos!$B$3:$K$12,$C$4+2,$E$4+2) -> 126 | E9: =Kernels!B7 -> 1 | F9: =Kernels!C7 -> 1 | G9: =Kernels!D7 -> 1 | H9: =A9*E9 -> 127 | I9: =B9*F9 -> 134 | J9: =C9*G9 -> 126
E11: Factor N | F11: =Kernels!F6 -> 9 | H11: Suma | I11: =SUM(H7:J9) -> 1048
H12: Salida (Suma/N) | I12: =I11/$F$11 -> 116.44444
A14: Filtro Promedio 3×3 (normalizado)
A15: i\j | B15: 0 | C15: 1 | D15: 2 | E15: 3 | F15: 4 | G15: 5 | H15: 6 | I15: 7 | J15: 8 | K15: 9
A16: 0 | B16: =IF(AND($A16>=1,$A16<=8,B$15>=1,B$15<=8),(INDEX(Kernels!$B$5:$D$7,1,1)*INDEX(Datos!$B$3:$K$12,($A16+1)+-1,(B$15+1)+-1)+INDEX(Kernels!$B$5:$D$7,1,2)*INDEX(Datos!$B$3:$K$12,($A16+1)+-1,(B$15+1)+0)+INDEX(Kernels!$B$5:$D$7,1,3)*INDEX(Datos!$B$3:$K$12,($A16+1)+-1,(B$15+1)+1)+INDEX(Kernels!$B$5:$D$7,2,1)*INDEX(Datos!$B$3:$K$12,($A16+1)+0,(B$15+1)+-1)+INDEX(Kernels!$B$5:$D$7,2,2)*INDEX(Datos!$B$3:$K$12,($A16+1)+0,(B$15+1)+0)+INDEX(Kernels!$B$5:$D$7,2,3)*INDEX(Datos!$B$3:$K$12,($A16+1)+0,(B$15+1)+1)+INDEX(Kernels!$B$5:$D$7,3,1)*INDEX(Datos!$B$3:$K$12,($A16+1)+1,(B$15+1)+-1)+INDEX(Kernels!$B$5:$D$7,3,2)*INDEX(Datos!$B$3:$K$12,($A16+1)+1,(B$15+1)+0)+INDEX(Kernels!$B$5:$D$7,3,3)*INDEX(Datos!$B$3:$K$12,($A16+1)+1,(B$15+1)+1))/Kernels!$F$6,"") | C16: =IF(AND($A16>=1,$A16<=8,C$15>=1,C$15<=8),(INDEX(Kernels!$B$5:$D$7,1,1)*INDEX(Datos!$B$3:$K$12,($A16+1)+-1,(C$15+1)+-1)+INDEX(Kernels!$B$5:$D$7,1,2)*INDEX(Datos!$B$3:$K$12,($A16+1)+-1,(C$15+1)+0)+INDEX(Kernels!$B$5:$D$7,1,3)*INDEX(Datos!$B$3:$K$12,($A16+1)+-1,(C$15+1)+1)+INDEX(Kernels!$B$5:$D$7,2,1)*INDEX(Datos!$B$3:$K$12,($A16+1)+0,(C$15+1)+-1)+INDEX(Kernels!$B$5:$D$7,2,2)*INDEX(Datos!$B$3:$K$12,($A16+1)+0,(C$15+1)+0)+INDEX(Kernels!$B$5:$D$7,2,3)*INDEX(Datos!$B$3:$K$12,($A16+1)+0,(C$15+1)+1)+INDEX(Kernels!$B$5:$D$7,3,1)*INDEX(Datos!$B$3:$K$12,($A16+1)+1,(C$15+1)+-1)+INDEX(Kernels!$B$5:$D$7,3,2)*INDEX(Datos!$B$3:$K$12,($A16+1)+1,(C$15+1)+0)+INDEX(Kernels!$B$5:$D$7,3,3)*INDEX(Datos!$B$3:$K$12,($A16+1)+1,(C$15+1)+1))/Kernels!$F$6,"") | D16: =IF(AND($A16>=1,$A16<=8,D$15>=1,D$15<=8),(INDEX(Kernels!$B$5:$D$7,1,1)*INDEX(Datos!$B$3:$K$12,($A16+1)+-1,(D$15+1)+-1)+INDEX(Kernels!$B$5:$D$7,1,2)*INDEX(Datos!$B$3:$K$12,($A16+1)+-1,(D$15+1)+0)+INDEX(Kernels!$B$5:$D$7,1,3)*INDEX(Datos!$B$3:$K$12,($A16+1)+-1,(D$15+1)+1)+INDEX(Kernels!$B$5:$D$7,2,1)*INDEX(Datos!$B$3:$K$12,($A16+1)+0,(D$15+1)+-1)+INDEX(Kernels!$B$5:$D$7,2,2)*INDEX(Datos!$B$3:$K$12,($A16+1)+0,(D$15+1)+0)+INDEX(Kernels!$B$5:$D$7,2,3)*INDEX(Datos!$B$3:$K$12,($A16+1)+0,(D$15+1)+1)+INDEX(Kernels!$B$5:$D$7,3,1)*INDEX(Datos!$B$3:$K$12,($A16+1)+1,(D$15+1)+-1)+INDEX(Kernels!$B$5:$D$7,3,2)*INDEX(Datos!$B$3:$K$12,($A16+1)+1,(D$15+1)+0)+INDEX(Kernels!$B$5:$D$7,3,3)*INDEX(Datos!$B$3:$K$12,($A16+1)+1,(D$15+1)+1))/Kernels!$F$6,"") | E16: =IF(AND($A16>=1,$A16<=8,E$15>=1,E$15<=8),(INDEX(Kernels!$B$5:$D$7,1,1)*INDEX(Datos!$B$3:$K$12,($A16+1)+-1,(E$15+1)+-1)+INDEX(Kernels!$B$5:$D$7,1,2)*INDEX(Datos!$B$3:$K$12,($A16+1)+-1,(E$15+1)+0)+INDEX(Kernels!$B$5:$D$7,1,3)*INDEX(Datos!$B$3:$K$12,($A16+1)+-1,(E$15+1)+1)+INDEX(Kernels!$B$5:$D$7,2,1)*INDEX(Datos!$B$3:$K$12,($A16+1)+0,(E$15+1)+-1)+INDEX(Kernels!$B$5:$D$7,2,2)*INDEX(Datos!$B$3:$K$12,($A16+1)+0,(E$15+1)+0)+INDEX(Kernels!$B$5:$D$7,2,3)*INDEX(Datos!$B$3:$K$12,($A16+1)+0,(E$15+1)+1)+INDEX(Kernels!$B$5:$D$7,3,1)*INDEX(Datos!$B$3:$K$12,($A16+1)+1,(E$15+1)+-1)+INDEX(Kernels!$B$5:$D$7,3,2)*INDEX(Datos!$B$3:$K$12,($A16+1)+1,(E$15+1)+0)+INDEX(Kernels!$B$5:$D$7,3,3)*INDEX(Datos!$B$3:$K$12,($A16+1)+1,(E$15+1)+1))/Kernels!$F$6,"") | F16: =IF(AND($A16>=1,$A16<=8,F$15>=1,F$15<=8),(INDEX(Kernels!$B$5:$D$7,1,1)*INDEX(Datos!$B$3:$K$12,($A16+1)+-1,(F$15+1)+-1)+INDEX(Kernels!$B$5:$D$7,1,2)*INDEX(Datos!$B$3:$K$12,($A16+1)+-1,(F$15+1)+0)+INDEX(Kernels!$B$5:$D$7,1,3)*INDEX(Datos!$B$3:$K$12,($A16+1)+-1,(F$15+1)+1)+INDEX(Kernels!$B$5:$D$7,2,1)*INDEX(Datos!$B$3:$K$12,($A16+1)+0,(F$15+1)+-1)+INDEX(Kernels!$B$5:$D$7,2,2)*INDEX(Datos!$B$3:$K$12,($A16+1)+0,(F$15+1)+0)+INDEX(Kernels!$B$5:$D$7,2,3)*INDEX(Datos!$B$3:$K$12,($A16+1)+0,(F$15+1)+1)+INDEX(Kernels!$B$5:$D$7,3,1)*INDEX(Datos!$B$3:$K$12,($A16+1)+1,(F$15+1)+-1)+INDEX(Kernels!$B$5:$D$7,3,2)*INDEX(Datos!$B$3:$K$12,($A16+1)+1,(F$15+1)+0)+INDEX(Kernels!$B$5:$D$7,3,3)*INDEX(Datos!$B$3:$K$12,($A16+1)+1,(F$15+1)+1))/Kernels!$F$6,"") | G16: =IF(AND($A16>=1,$A16<=8,G$15>=1,G$15<=8),(INDEX(Kernels!$B$5:$D$7,1,1)*INDEX(Datos!$B$3:$K$12,($A16+1)+-1,(G$15+1)+-1)+INDEX(Kernels!$B$5:$D$7,1,2)*INDEX(Datos!$B$3:$K$12,($A16+1)+-1,(G$15+1)+0)+INDEX(Kernels!$B$5:$D$7,1,3)*INDEX(Datos!$B$3:$K$12,($A16+1)+-1,(G$15+1)+1)+INDEX(Kernels!$B$5:$D$7,2,1)*INDEX(Datos!$B$3:$K$12,($A16+1)+0,(G$15+1)+-1)+INDEX(Kernels!$B$5:$D$7,2,2)*INDEX(Datos!$B$3:$K$12,($A16+1)+0,(G$15+1)+0)+INDEX(Kernels!$B$5:$D$7,2,3)*INDEX(Datos!$B$3:$K$12,($A16+1)+0,(G$15+1)+1)+INDEX(Kernels!$B$5:$D$7,3,1)*INDEX(Datos!$B$3:$K$12,($A16+1)+1,(G$15+1)+-1)+INDEX(Kernels!$B$5:$D$7,3,2)*INDEX(Datos!$B$3:$K$12,($A16+1)+1,(G$15+1)+0)+INDEX(Kernels!$B$5:$D$7,3,3)*INDEX(Datos!$B$3:$K$12,($A16+1)+1,(G$15+1)+1))/Kernels!$F$6,"") | H16: =IF(AND($A16>=1,$A16<=8,H$15>=1,H$15<=8),(INDEX(Kernels!$B$5:$D$7,1,1)*INDEX(Datos!$B$3:$K$12,($A16+1)+-1,(H$15+1)+-1)+INDEX(Kernels!$B$5:$D$7,1,2)*INDEX(Datos!$B$3:$K$12,($A16+1)+-1,(H$15+1)+0)+INDEX(Kernels!$B$5:$D$7,1,3)*INDEX(Datos!$B$3:$K$12,($A16+1)+-1,(H$15+1)+1)+INDEX(Kernels!$B$5:$D$7,2,1)*INDEX(Datos!$B$3:$K$12,($A16+1)+0,(H$15+1)+-1)+INDEX(Kernels!$B$5:$D$7,2,2)*INDEX(Datos!$B$3:$K$12,($A16+1)+0,(H$15+1)+0)+INDEX(Kernels!$B$5:$D$7,2,3)*INDEX(Datos!$B$3:$K$12,($A16+1)+0,(H$15+1)+1)+INDEX(Kernels!$B$5:$D$7,3,1)*INDEX(Datos!$B$3:$K$12,($A16+1)+1,(H$15+1)+-1)+INDEX(Kernels!$B$5:$D$7,3,2)*INDEX(Datos!$B$3:$K$12,($A16+1)+1,(H$15+1)+0)+INDEX(Kernels!$B$5:$D$7,3,3)*INDEX(Datos!$B$3:$K$12,($A16+1)+1,(H$15+1)+1))/Kernels!$F$6,"") | I16: =IF(AND($A16>=1,$A16<=8,I$15>=1,I$15<=8),(INDEX(Kernels!$B$5:$D$7,1,1)*INDEX(Datos!$B$3:$K$12,($A16+1)+-1,(I$15+1)+-1)+INDEX(Kernels!$B$5:$D$7,1,2)*INDEX(Datos!$B$3:$K$12,($A16+1)+-1,(I$15+1)+0)+INDEX(Kernels!$B$5:$D$7,1,3)*INDEX(Datos!$B$3:$K$12,($A16+1)+-1,(I$15+1)+1)+INDEX(Kernels!$B$5:$D$7,2,1)*INDEX(Datos!$B$3:$K$12,($A16+1)+0,(I$15+1)+-1)+INDEX(Kernels!$B$5:$D$7,2,2)*INDEX(Datos!$B$3:$K$12,($A16+1)+0,(I$15+1)+0)+INDEX(Kernels!$B$5:$D$7,2,3)*INDEX(Datos!$B$3:$K$12,($A16+1)+0,(I$15+1)+1)+INDEX(Kernels!$B$5:$D$7,3,1)*INDEX(Datos!$B$3:$K$12,($A16+1)+1,(I$15+1)+-1)+INDEX(Kernels!$B$5:$D$7,3,2)*INDEX(Datos!$B$3:$K$12,($A16+1)+1,(I$15+1)+0)+INDEX(Kernels!$B$5:$D$7,3,3)*INDEX(Datos!$B$3:$K$12,($A16+1)+1,(I$15+1)+1))/Kernels!$F$6,"") | ... K16: =IF(AND($A16>=1,$A16<=8,K$15>=1,K$15<=8),(INDEX(Kernels!$B$5:$D$7,1,1)*INDEX(Datos!$B$3:$K$12,($A16+1)+-1,(K$15+1)+-1)+INDEX(Kernels!$B$5:$D$7,1,2)*INDEX(Datos!$B$3:$K$12,($A16+1)+-1,(K$15+1)+0)+INDEX(Kernels!$B$5:$D$7,1,3)*INDEX(Datos!$B$3:$K$12,($A16+1)+-1,(K$15+1)+1)+INDEX(Kernels!$B$5:$D$7,2,1)*INDEX(Datos!$B$3:$K$12,($A16+1)+0,(K$15+1)+-1)+INDEX(Kernels!$B$5:$D$7,2,2)*INDEX(Datos!$B$3:$K$12,($A16+1)+0,(K$15+1)+0)+INDEX(Kernels!$B$5:$D$7,2,3)*INDEX(Datos!$B$3:$K$12,($A16+1)+0,(K$15+1)+1)+INDEX(Kernels!$B$5:$D$7,3,1)*INDEX(Datos!$B$3:$K$12,($A16+1)+1,(K$15+1)+-1)+INDEX(Kernels!$B$5:$D$7,3,2)*INDEX(Datos!$B$3:$K$12,($A16+1)+1,(K$15+1)+0)+INDEX(Kernels!$B$5:$D$7,3,3)*INDEX(Datos!$B$3:$K$12,($A16+1)+1,(K$15+1)+1))/Kernels!$F$6,"")
A17: 1 | B17: =IF(AND($A17>=1,$A17<=8,B$15>=1,B$15<=8),(INDEX(Kernels!$B$5:$D$7,1,1)*INDEX(Datos!$B$3:$K$12,($A17+1)+-1,(B$15+1)+-1)+INDEX(Kernels!$B$5:$D$7,1,2)*INDEX(Datos!$B$3:$K$12,($A17+1)+-1,(B$15+1)+0)+INDEX(Kernels!$B$5:$D$7,1,3)*INDEX(Datos!$B$3:$K$12,($A17+1)+-1,(B$15+1)+1)+INDEX(Kernels!$B$5:$D$7,2,1)*INDEX(Datos!$B$3:$K$12,($A17+1)+0,(B$15+1)+-1)+INDEX(Kernels!$B$5:$D$7,2,2)*INDEX(Datos!$B$3:$K$12,($A17+1)+0,(B$15+1)+0)+INDEX(Kernels!$B$5:$D$7,2,3)*INDEX(Datos!$B$3:$K$12,($A17+1)+0,(B$15+1)+1)+INDEX(Kernels!$B$5:$D$7,3,1)*INDEX(Datos!$B$3:$K$12,($A17+1)+1,(B$15+1)+-1)+INDEX(Kernels!$B$5:$D$7,3,2)*INDEX(Datos!$B$3:$K$12,($A17+1)+1,(B$15+1)+0)+INDEX(Kernels!$B$5:$D$7,3,3)*INDEX(Datos!$B$3:$K$12,($A17+1)+1,(B$15+1)+1))/Kernels!$F$6,"") | C17: =IF(AND($A17>=1,$A17<=8,C$15>=1,C$15<=8),(INDEX(Kernels!$B$5:$D$7,1,1)*INDEX(Datos!$B$3:$K$12,($A17+1)+-1,(C$15+1)+-1)+INDEX(Kernels!$B$5:$D$7,1,2)*INDEX(Datos!$B$3:$K$12,($A17+1)+-1,(C$15+1)+0)+INDEX(Kernels!$B$5:$D$7,1,3)*INDEX(Datos!$B$3:$K$12,($A17+1)+-1,(C$15+1)+1)+INDEX(Kernels!$B$5:$D$7,2,1)*INDEX(Datos!$B$3:$K$12,($A17+1)+0,(C$15+1)+-1)+INDEX(Kernels!$B$5:$D$7,2,2)*INDEX(Datos!$B$3:$K$12,($A17+1)+0,(C$15+1)+0)+INDEX(Kernels!$B$5:$D$7,2,3)*INDEX(Datos!$B$3:$K$12,($A17+1)+0,(C$15+1)+1)+INDEX(Kernels!$B$5:$D$7,3,1)*INDEX(Datos!$B$3:$K$12,($A17+1)+1,(C$15+1)+-1)+INDEX(Kernels!$B$5:$D$7,3,2)*INDEX(Datos!$B$3:$K$12,($A17+1)+1,(C$15+1)+0)+INDEX(Kernels!$B$5:$D$7,3,3)*INDEX(Datos!$B$3:$K$12,($A17+1)+1,(C$15+1)+1))/Kernels!$F$6,"") -> 112.33333 | D17: =IF(AND($A17>=1,$A17<=8,D$15>=1,D$15<=8),(INDEX(Kernels!$B$5:$D$7,1,1)*INDEX(Datos!$B$3:$K$12,($A17+1)+-1,(D$15+1)+-1)+INDEX(Kernels!$B$5:$D$7,1,2)*INDEX(Datos!$B$3:$K$12,($A17+1)+-1,(D$15+1)+0)+INDEX(Kernels!$B$5:$D$7,1,3)*INDEX(Datos!$B$3:$K$12,($A17+1)+-1,(D$15+1)+1)+INDEX(Kernels!$B$5:$D$7,2,1)*INDEX(Datos!$B$3:$K$12,($A17+1)+0,(D$15+1)+-1)+INDEX(Kernels!$B$5:$D$7,2,2)*INDEX(Datos!$B$3:$K$12,($A17+1)+0,(D$15+1)+0)+INDEX(Kernels!$B$5:$D$7,2,3)*INDEX(Datos!$B$3:$K$12,($A17+1)+0,(D$15+1)+1)+INDEX(Kernels!$B$5:$D$7,3,1)*INDEX(Datos!$B$3:$K$12,($A17+1)+1,(D$15+1)+-1)+INDEX(Kernels!$B$5:$D$7,3,2)*INDEX(Datos!$B$3:$K$12,($A17+1)+1,(D$15+1)+0)+INDEX(Kernels!$B$5:$D$7,3,3)*INDEX(Datos!$B$3:$K$12,($A17+1)+1,(D$15+1)+1))/Kernels!$F$6,"") -> 109 | E17: =IF(AND($A17>=1,$A17<=8,E$15>=1,E$15<=8),(INDEX(Kernels!$B$5:$D$7,1,1)*INDEX(Datos!$B$3:$K$12,($A17+1)+-1,(E$15+1)+-1)+INDEX(Kernels!$B$5:$D$7,1,2)*INDEX(Datos!$B$3:$K$12,($A17+1)+-1,(E$15+1)+0)+INDEX(Kernels!$B$5:$D$7,1,3)*INDEX(Datos!$B$3:$K$12,($A17+1)+-1,(E$15+1)+1)+INDEX(Kernels!$B$5:$D$7,2,1)*INDEX(Datos!$B$3:$K$12,($A17+1)+0,(E$15+1)+-1)+INDEX(Kernels!$B$5:$D$7,2,2)*INDEX(Datos!$B$3:$K$12,($A17+1)+0,(E$15+1)+0)+INDEX(Kernels!$B$5:$D$7,2,3)*INDEX(Datos!$B$3:$K$12,($A17+1)+0,(E$15+1)+1)+INDEX(Kernels!$B$5:$D$7,3,1)*INDEX(Datos!$B$3:$K$12,($A17+1)+1,(E$15+1)+-1)+INDEX(Kernels!$B$5:$D$7,3,2)*INDEX(Datos!$B$3:$K$12,($A17+1)+1,(E$15+1)+0)+INDEX(Kernels!$B$5:$D$7,3,3)*INDEX(Datos!$B$3:$K$12,($A17+1)+1,(E$15+1)+1))/Kernels!$F$6,"") -> 103.88889 | F17: =IF(AND($A17>=1,$A17<=8,F$15>=1,F$15<=8),(INDEX(Kernels!$B$5:$D$7,1,1)*INDEX(Datos!$B$3:$K$12,($A17+1)+-1,(F$15+1)+-1)+INDEX(Kernels!$B$5:$D$7,1,2)*INDEX(Datos!$B$3:$K$12,($A17+1)+-1,(F$15+1)+0)+INDEX(Kernels!$B$5:$D$7,1,3)*INDEX(Datos!$B$3:$K$12,($A17+1)+-1,(F$15+1)+1)+INDEX(Kernels!$B$5:$D$7,2,1)*INDEX(Datos!$B$3:$K$12,($A17+1)+0,(F$15+1)+-1)+INDEX(Kernels!$B$5:$D$7,2,2)*INDEX(Datos!$B$3:$K$12,($A17+1)+0,(F$15+1)+0)+INDEX(Kernels!$B$5:$D$7,2,3)*INDEX(Datos!$B$3:$K$12,($A17+1)+0,(F$15+1)+1)+INDEX(Kernels!$B$5:$D$7,3,1)*INDEX(Datos!$B$3:$K$12,($A17+1)+1,(F$15+1)+-1)+INDEX(Kernels!$B$5:$D$7,3,2)*INDEX(Datos!$B$3:$K$12,($A17+1)+1,(F$15+1)+0)+INDEX(Kernels!$B$5:$D$7,3,3)*INDEX(Datos!$B$3:$K$12,($A17+1)+1,(F$15+1)+1))/Kernels!$F$6,"") -> 93.444444 | G17: =IF(AND($A17>=1,$A17<=8,G$15>=1,G$15<=8),(INDEX(Kernels!$B$5:$D$7,1,1)*INDEX(Datos!$B$3:$K$12,($A17+1)+-1,(G$15+1)+-1)+INDEX(Kernels!$B$5:$D$7,1,2)*INDEX(Datos!$B$3:$K$12,($A17+1)+-1,(G$15+1)+0)+INDEX(Kernels!$B$5:$D$7,1,3)*INDEX(Datos!$B$3:$K$12,($A17+1)+-1,(G$15+1)+1)+INDEX(Kernels!$B$5:$D$7,2,1)*INDEX(Datos!$B$3:$K$12,($A17+1)+0,(G$15+1)+-1)+INDEX(Kernels!$B$5:$D$7,2,2)*INDEX(Datos!$B$3:$K$12,($A17+1)+0,(G$15+1)+0)+INDEX(Kernels!$B$5:$D$7,2,3)*INDEX(Datos!$B$3:$K$12,($A17+1)+0,(G$15+1)+1)+INDEX(Kernels!$B$5:$D$7,3,1)*INDEX(Datos!$B$3:$K$12,($A17+1)+1,(G$15+1)+-1)+INDEX(Kernels!$B$5:$D$7,3,2)*INDEX(Datos!$B$3:$K$12,($A17+1)+1,(G$15+1)+0)+INDEX(Kernels!$B$5:$D$7,3,3)*INDEX(Datos!$B$3:$K$12,($A17+1)+1,(G$15+1)+1))/Kernels!$F$6,"") -> 82.666667 | H17: =IF(AND($A17>=1,$A17<=8,H$15>=1,H$15<=8),(INDEX(Kernels!$B$5:$D$7,1,1)*INDEX(Datos!$B$3:$K$12,($A17+1)+-1,(H$15+1)+-1)+INDEX(Kernels!$B$5:$D$7,1,2)*INDEX(Datos!$B$3:$K$12,($A17+1)+-1,(H$15+1)+0)+INDEX(Kernels!$B$5:$D$7,1,3)*INDEX(Datos!$B$3:$K$12,($A17+1)+-1,(H$15+1)+1)+INDEX(Kernels!$B$5:$D$7,2,1)*INDEX(Datos!$B$3:$K$12,($A17+1)+0,(H$15+1)+-1)+INDEX(Kernels!$B$5:$D$7,2,2)*INDEX(Datos!$B$3:$K$12,($A17+1)+0,(H$15+1)+0)+INDEX(Kernels!$B$5:$D$7,2,3)*INDEX(Datos!$B$3:$K$12,($A17+1)+0,(H$15+1)+1)+INDEX(Kernels!$B$5:$D$7,3,1)*INDEX(Datos!$B$3:$K$12,($A17+1)+1,(H$15+1)+-1)+INDEX(Kernels!$B$5:$D$7,3,2)*INDEX(Datos!$B$3:$K$12,($A17+1)+1,(H$15+1)+0)+INDEX(Kernels!$B$5:$D$7,3,3)*INDEX(Datos!$B$3:$K$12,($A17+1)+1,(H$15+1)+1))/Kernels!$F$6,"") -> 80.444444 | I17: =IF(AND($A17>=1,$A17<=8,I$15>=1,I$15<=8),(INDEX(Kernels!$B$5:$D$7,1,1)*INDEX(Datos!$B$3:$K$12,($A17+1)+-1,(I$15+1)+-1)+INDEX(Kernels!$B$5:$D$7,1,2)*INDEX(Datos!$B$3:$K$12,($A17+1)+-1,(I$15+1)+0)+INDEX(Kernels!$B$5:$D$7,1,3)*INDEX(Datos!$B$3:$K$12,($A17+1)+-1,(I$15+1)+1)+INDEX(Kernels!$B$5:$D$7,2,1)*INDEX(Datos!$B$3:$K$12,($A17+1)+0,(I$15+1)+-1)+INDEX(Kernels!$B$5:$D$7,2,2)*INDEX(Datos!$B$3:$K$12,($A17+1)+0,(I$15+1)+0)+INDEX(Kernels!$B$5:$D$7,2,3)*INDEX(Datos!$B$3:$K$12,($A17+1)+0,(I$15+1)+1)+INDEX(Kernels!$B$5:$D$7,3,1)*INDEX(Datos!$B$3:$K$12,($A17+1)+1,(I$15+1)+-1)+INDEX(Kernels!$B$5:$D$7,3,2)*INDEX(Datos!$B$3:$K$12,($A17+1)+1,(I$15+1)+0)+INDEX(Kernels!$B$5:$D$7,3,3)*INDEX(Datos!$B$3:$K$12,($A17+1)+1,(I$15+1)+1))/Kernels!$F$6,"") -> 75.777778 | ... K17: =IF(AND($A17>=1,$A17<=8,K$15>=1,K$15<=8),(INDEX(Kernels!$B$5:$D$7,1,1)*INDEX(Datos!$B$3:$K$12,($A17+1)+-1,(K$15+1)+-1)+INDEX(Kernels!$B$5:$D$7,1,2)*INDEX(Datos!$B$3:$K$12,($A17+1)+-1,(K$15+1)+0)+INDEX(Kernels!$B$5:$D$7,1,3)*INDEX(Datos!$B$3:$K$12,($A17+1)+-1,(K$15+1)+1)+INDEX(Kernels!$B$5:$D$7,2,1)*INDEX(Datos!$B$3:$K$12,($A17+1)+0,(K$15+1)+-1)+INDEX(Kernels!$B$5:$D$7,2,2)*INDEX(Datos!$B$3:$K$12,($A17+1)+0,(K$15+1)+0)+INDEX(Kernels!$B$5:$D$7,2,3)*INDEX(Datos!$B$3:$K$12,($A17+1)+0,(K$15+1)+1)+INDEX(Kernels!$B$5:$D$7,3,1)*INDEX(Datos!$B$3:$K$12,($A17+1)+1,(K$15+1)+-1)+INDEX(Kernels!$B$5:$D$7,3,2)*INDEX(Datos!$B$3:$K$12,($A17+1)+1,(K$15+1)+0)+INDEX(Kernels!$B$5:$D$7,3,3)*INDEX(Datos!$B$3:$K$12,($A17+1)+1,(K$15+1)+1))/Kernels!$F$6,"")
A18: 2 | B18: =IF(AND($A18>=1,$A18<=8,B$15>=1,B$15<=8),(INDEX(Kernels!$B$5:$D$7,1,1)*INDEX(Datos!$B$3:$K$12,($A18+1)+-1,(B$15+1)+-1)+INDEX(Kernels!$B$5:$D$7,1,2)*INDEX(Datos!$B$3:$K$12,($A18+1)+-1,(B$15+1)+0)+INDEX(Kernels!$B$5:$D$7,1,3)*INDEX(Datos!$B$3:$K$12,($A18+1)+-1,(B$15+1)+1)+INDEX(Kernels!$B$5:$D$7,2,1)*INDEX(Datos!$B$3:$K$12,($A18+1)+0,(B$15+1)+-1)+INDEX(Kernels!$B$5:$D$7,2,2)*INDEX(Datos!$B$3:$K$12,($A18+1)+0,(B$15+1)+0)+INDEX(Kernels!$B$5:$D$7,2,3)*INDEX(Datos!$B$3:$K$12,($A18+1)+0,(B$15+1)+1)+INDEX(Kernels!$B$5:$D$7,3,1)*INDEX(Datos!$B$3:$K$12,($A18+1)+1,(B$15+1)+-1)+INDEX(Kernels!$B$5:$D$7,3,2)*INDEX(Datos!$B$3:$K$12,($A18+1)+1,(B$15+1)+0)+INDEX(Kernels!$B$5:$D$7,3,3)*INDEX(Datos!$B$3:$K$12,($A18+1)+1,(B$15+1)+1))/Kernels!$F$6,"") | C18: =IF(AND($A18>=1,$A18<=8,C$15>=1,C$15<=8),(INDEX(Kernels!$B$5:$D$7,1,1)*INDEX(Datos!$B$3:$K$12,($A18+1)+-1,(C$15+1)+-1)+INDEX(Kernels!$B$5:$D$7,1,2)*INDEX(Datos!$B$3:$K$12,($A18+1)+-1,(C$15+1)+0)+INDEX(Kernels!$B$5:$D$7,1,3)*INDEX(Datos!$B$3:$K$12,($A18+1)+-1,(C$15+1)+1)+INDEX(Kernels!$B$5:$D$7,2,1)*INDEX(Datos!$B$3:$K$12,($A18+1)+0,(C$15+1)+-1)+INDEX(Kernels!$B$5:$D$7,2,2)*INDEX(Datos!$B$3:$K$12,($A18+1)+0,(C$15+1)+0)+INDEX(Kernels!$B$5:$D$7,2,3)*INDEX(Datos!$B$3:$K$12,($A18+1)+0,(C$15+1)+1)+INDEX(Kernels!$B$5:$D$7,3,1)*INDEX(Datos!$B$3:$K$12,($A18+1)+1,(C$15+1)+-1)+INDEX(Kernels!$B$5:$D$7,3,2)*INDEX(Datos!$B$3:$K$12,($A18+1)+1,(C$15+1)+0)+INDEX(Kernels!$B$5:$D$7,3,3)*INDEX(Datos!$B$3:$K$12,($A18+1)+1,(C$15+1)+1))/Kernels!$F$6,"") -> 118.55556 | D18: =IF(AND($A18>=1,$A18<=8,D$15>=1,D$15<=8),(INDEX(Kernels!$B$5:$D$7,1,1)*INDEX(Datos!$B$3:$K$12,($A18+1)+-1,(D$15+1)+-1)+INDEX(Kernels!$B$5:$D$7,1,2)*INDEX(Datos!$B$3:$K$12,($A18+1)+-1,(D$15+1)+0)+INDEX(Kernels!$B$5:$D$7,1,3)*INDEX(Datos!$B$3:$K$12,($A18+1)+-1,(D$15+1)+1)+INDEX(Kernels!$B$5:$D$7,2,1)*INDEX(Datos!$B$3:$K$12,($A18+1)+0,(D$15+1)+-1)+INDEX(Kernels!$B$5:$D$7,2,2)*INDEX(Datos!$B$3:$K$12,($A18+1)+0,(D$15+1)+0)+INDEX(Kernels!$B$5:$D$7,2,3)*INDEX(Datos!$B$3:$K$12,($A18+1)+0,(D$15+1)+1)+INDEX(Kernels!$B$5:$D$7,3,1)*INDEX(Datos!$B$3:$K$12,($A18+1)+1,(D$15+1)+-1)+INDEX(Kernels!$B$5:$D$7,3,2)*INDEX(Datos!$B$3:$K$12,($A18+1)+1,(D$15+1)+0)+INDEX(Kernels!$B$5:$D$7,3,3)*INDEX(Datos!$B$3:$K$12,($A18+1)+1,(D$15+1)+1))/Kernels!$F$6,"") -> 116.88889 | E18: =IF(AND($A18>=1,$A18<=8,E$15>=1,E$15<=8),(INDEX(Kernels!$B$5:$D$7,1,1)*INDEX(Datos!$B$3:$K$12,($A18+1)+-1,(E$15+1)+-1)+INDEX(Kernels!$B$5:$D$7,1,2)*INDEX(Datos!$B$3:$K$12,($A18+1)+-1,(E$15+1)+0)+INDEX(Kernels!$B$5:$D$7,1,3)*INDEX(Datos!$B$3:$K$12,($A18+1)+-1,(E$15+1)+1)+INDEX(Kernels!$B$5:$D$7,2,1)*INDEX(Datos!$B$3:$K$12,($A18+1)+0,(E$15+1)+-1)+INDEX(Kernels!$B$5:$D$7,2,2)*INDEX(Datos!$B$3:$K$12,($A18+1)+0,(E$15+1)+0)+INDEX(Kernels!$B$5:$D$7,2,3)*INDEX(Datos!$B$3:$K$12,($A18+1)+0,(E$15+1)+1)+INDEX(Kernels!$B$5:$D$7,3,1)*INDEX(Datos!$B$3:$K$12,($A18+1)+1,(E$15+1)+-1)+INDEX(Kernels!$B$5:$D$7,3,2)*INDEX(Datos!$B$3:$K$12,($A18+1)+1,(E$15+1)+0)+INDEX(Kernels!$B$5:$D$7,3,3)*INDEX(Datos!$B$3:$K$12,($A18+1)+1,(E$15+1)+1))/Kernels!$F$6,"") -> 105.11111 | F18: =IF(AND($A18>=1,$A18<=8,F$15>=1,F$15<=8),(INDEX(Kernels!$B$5:$D$7,1,1)*INDEX(Datos!$B$3:$K$12,($A18+1)+-1,(F$15+1)+-1)+INDEX(Kernels!$B$5:$D$7,1,2)*INDEX(Datos!$B$3:$K$12,($A18+1)+-1,(F$15+1)+0)+INDEX(Kernels!$B$5:$D$7,1,3)*INDEX(Datos!$B$3:$K$12,($A18+1)+-1,(F$15+1)+1)+INDEX(Kernels!$B$5:$D$7,2,1)*INDEX(Datos!$B$3:$K$12,($A18+1)+0,(F$15+1)+-1)+INDEX(Kernels!$B$5:$D$7,2,2)*INDEX(Datos!$B$3:$K$12,($A18+1)+0,(F$15+1)+0)+INDEX(Kernels!$B$5:$D$7,2,3)*INDEX(Datos!$B$3:$K$12,($A18+1)+0,(F$15+1)+1)+INDEX(Kernels!$B$5:$D$7,3,1)*INDEX(Datos!$B$3:$K$12,($A18+1)+1,(F$15+1)+-1)+INDEX(Kernels!$B$5:$D$7,3,2)*INDEX(Datos!$B$3:$K$12,($A18+1)+1,(F$15+1)+0)+INDEX(Kernels!$B$5:$D$7,3,3)*INDEX(Datos!$B$3:$K$12,($A18+1)+1,(F$15+1)+1))/Kernels!$F$6,"") -> 92.444444 | G18: =IF(AND($A18>=1,$A18<=8,G$15>=1,G$15<=8),(INDEX(Kernels!$B$5:$D$7,1,1)*INDEX(Datos!$B$3:$K$12,($A18+1)+-1,(G$15+1)+-1)+INDEX(Kernels!$B$5:$D$7,1,2)*INDEX(Datos!$B$3:$K$12,($A18+1)+-1,(G$15+1)+0)+INDEX(Kernels!$B$5:$D$7,1,3)*INDEX(Datos!$B$3:$K$12,($A18+1)+-1,(G$15+1)+1)+INDEX(Kernels!$B$5:$D$7,2,1)*INDEX(Datos!$B$3:$K$12,($A18+1)+0,(G$15+1)+-1)+INDEX(Kernels!$B$5:$D$7,2,2)*INDEX(Datos!$B$3:$K$12,($A18+1)+0,(G$15+1)+0)+INDEX(Kernels!$B$5:$D$7,2,3)*INDEX(Datos!$B$3:$K$12,($A18+1)+0,(G$15+1)+1)+INDEX(Kernels!$B$5:$D$7,3,1)*INDEX(Datos!$B$3:$K$12,($A18+1)+1,(G$15+1)+-1)+INDEX(Kernels!$B$5:$D$7,3,2)*INDEX(Datos!$B$3:$K$12,($A18+1)+1,(G$15+1)+0)+INDEX(Kernels!$B$5:$D$7,3,3)*INDEX(Datos!$B$3:$K$12,($A18+1)+1,(G$15+1)+1))/Kernels!$F$6,"") -> 90.777778 | H18: =IF(AND($A18>=1,$A18<=8,H$15>=1,H$15<=8),(INDEX(Kernels!$B$5:$D$7,1,1)*INDEX(Datos!$B$3:$K$12,($A18+1)+-1,(H$15+1)+-1)+INDEX(Kernels!$B$5:$D$7,1,2)*INDEX(Datos!$B$3:$K$12,($A18+1)+-1,(H$15+1)+0)+INDEX(Kernels!$B$5:$D$7,1,3)*INDEX(Datos!$B$3:$K$12,($A18+1)+-1,(H$15+1)+1)+INDEX(Kernels!$B$5:$D$7,2,1)*INDEX(Datos!$B$3:$K$12,($A18+1)+0,(H$15+1)+-1)+INDEX(Kernels!$B$5:$D$7,2,2)*INDEX(Datos!$B$3:$K$12,($A18+1)+0,(H$15+1)+0)+INDEX(Kernels!$B$5:$D$7,2,3)*INDEX(Datos!$B$3:$K$12,($A18+1)+0,(H$15+1)+1)+INDEX(Kernels!$B$5:$D$7,3,1)*INDEX(Datos!$B$3:$K$12,($A18+1)+1,(H$15+1)+-1)+INDEX(Kernels!$B$5:$D$7,3,2)*INDEX(Datos!$B$3:$K$12,($A18+1)+1,(H$15+1)+0)+INDEX(Kernels!$B$5:$D$7,3,3)*INDEX(Datos!$B$3:$K$12,($A18+1)+1,(H$15+1)+1))/Kernels!$F$6,"") -> 101.33333 | I18: =IF(AND($A18>=1,$A18<=8,I$15>=1,I$15<=8),(INDEX(Kernels!$B$5:$D$7,1,1)*INDEX(Datos!$B$3:$K$12,($A18+1)+-1,(I$15+1)+-1)+INDEX(Kernels!$B$5:$D$7,1,2)*INDEX(Datos!$B$3:$K$12,($A18+1)+-1,(I$15+1)+0)+INDEX(Kernels!$B$5:$D$7,1,3)*INDEX(Datos!$B$3:$K$12,($A18+1)+-1,(I$15+1)+1)+INDEX(Kernels!$B$5:$D$7,2,1)*INDEX(Datos!$B$3:$K$12,($A18+1)+0,(I$15+1)+-1)+INDEX(Kernels!$B$5:$D$7,2,2)*INDEX(Datos!$B$3:$K$12,($A18+1)+0,(I$15+1)+0)+INDEX(Kernels!$B$5:$D$7,2,3)*INDEX(Datos!$B$3:$K$12,($A18+1)+0,(I$15+1)+1)+INDEX(Kernels!$B$5:$D$7,3,1)*INDEX(Datos!$B$3:$K$12,($A18+1)+1,(I$15+1)+-1)+INDEX(Kernels!$B$5:$D$7,3,2)*INDEX(Datos!$B$3:$K$12,($A18+1)+1,(I$15+1)+0)+INDEX(Kernels!$B$5:$D$7,3,3)*INDEX(Datos!$B$3:$K$12,($A18+1)+1,(I$15+1)+1))/Kernels!$F$6,"") -> 110.33333 | ... K18: =IF(AND($A18>=1,$A18<=8,K$15>=1,K$15<=8),(INDEX(Kernels!$B$5:$D$7,1,1)*INDEX(Datos!$B$3:$K$12,($A18+1)+-1,(K$15+1)+-1)+INDEX(Kernels!$B$5:$D$7,1,2)*INDEX(Datos!$B$3:$K$12,($A18+1)+-1,(K$15+1)+0)+INDEX(Kernels!$B$5:$D$7,1,3)*INDEX(Datos!$B$3:$K$12,($A18+1)+-1,(K$15+1)+1)+INDEX(Kernels!$B$5:$D$7,2,1)*INDEX(Datos!$B$3:$K$12,($A18+1)+0,(K$15+1)+-1)+INDEX(Kernels!$B$5:$D$7,2,2)*INDEX(Datos!$B$3:$K$12,($A18+1)+0,(K$15+1)+0)+INDEX(Kernels!$B$5:$D$7,2,3)*INDEX(Datos!$B$3:$K$12,($A18+1)+0,(K$15+1)+1)+INDEX(Kernels!$B$5:$D$7,3,1)*INDEX(Datos!$B$3:$K$12,($A18+1)+1,(K$15+1)+-1)+INDEX(Kernels!$B$5:$D$7,3,2)*INDEX(Datos!$B$3:$K$12,($A18+1)+1,(K$15+1)+0)+INDEX(Kernels!$B$5:$D$7,3,3)*INDEX(Datos!$B$3:$K$12,($A18+1)+1,(K$15+1)+1))/Kernels!$F$6,"")
A19: 3 | B19: =IF(AND($A19>=1,$A19<=8,B$15>=1,B$15<=8),(INDEX(Kernels!$B$5:$D$7,1,1)*INDEX(Datos!$B$3:$K$12,($A19+1)+-1,(B$15+1)+-1)+INDEX(Kernels!$B$5:$D$7,1,2)*INDEX(Datos!$B$3:$K$12,($A19+1)+-1,(B$15+1)+0)+INDEX(Kernels!$B$5:$D$7,1,3)*INDEX(Datos!$B$3:$K$12,($A19+1)+-1,(B$15+1)+1)+INDEX(Kernels!$B$5:$D$7,2,1)*INDEX(Datos!$B$3:$K$12,($A19+1)+0,(B$15+1)+-1)+INDEX(Kernels!$B$5:$D$7,2,2)*INDEX(Datos!$B$3:$K$12,($A19+1)+0,(B$15+1)+0)+INDEX(Kernels!$B$5:$D$7,2,3)*INDEX(Datos!$B$3:$K$12,($A19+1)+0,(B$15+1)+1)+INDEX(Kernels!$B$5:$D$7,3,1)*INDEX(Datos!$B$3:$K$12,($A19+1)+1,(B$15+1)+-1)+INDEX(Kernels!$B$5:$D$7,3,2)*INDEX(Datos!$B$3:$K$12,($A19+1)+1,(B$15+1)+0)+INDEX(Kernels!$B$5:$D$7,3,3)*INDEX(Datos!$B$3:$K$12,($A19+1)+1,(B$15+1)+1))/Kernels!$F$6,"") | C19: =IF(AND($A19>=1,$A19<=8,C$15>=1,C$15<=8),(INDEX(Kernels!$B$5:$D$7,1,1)*INDEX(Datos!$B$3:$K$12,($A19+1)+-1,(C$15+1)+-1)+INDEX(Kernels!$B$5:$D$7,1,2)*INDEX(Datos!$B$3:$K$12,($A19+1)+-1,(C$15+1)+0)+INDEX(Kernels!$B$5:$D$7,1,3)*INDEX(Datos!$B$3:$K$12,($A19+1)+-1,(C$15+1)+1)+INDEX(Kernels!$B$5:$D$7,2,1)*INDEX(Datos!$B$3:$K$12,($A19+1)+0,(C$15+1)+-1)+INDEX(Kernels!$B$5:$D$7,2,2)*INDEX(Datos!$B$3:$K$12,($A19+1)+0,(C$15+1)+0)+INDEX(Kernels!$B$5:$D$7,2,3)*INDEX(Datos!$B$3:$K$12,($A19+1)+0,(C$15+1)+1)+INDEX(Kernels!$B$5:$D$7,3,1)*INDEX(Datos!$B$3:$K$12,($A19+1)+1,(C$15+1)+-1)+INDEX(Kernels!$B$5:$D$7,3,2)*INDEX(Datos!$B$3:$K$12,($A19+1)+1,(C$15+1)+0)+INDEX(Kernels!$B$5:$D$7,3,3)*INDEX(Datos!$B$3:$K$12,($A19+1)+1,(C$15+1)+1))/Kernels!$F$6,"") -> 124.44444 | D19: =IF(AND($A19>=1,$A19<=8,D$15>=1,D$15<=8),(INDEX(Kernels!$B$5:$D$7,1,1)*INDEX(Datos!$B$3:$K$12,($A19+1)+-1,(D$15+1)+-1)+INDEX(Kernels!$B$5:$D$7,1,2)*INDEX(Datos!$B$3:$K$12,($A19+1)+-1,(D$15+1)+0)+INDEX(Kernels!$B$5:$D$7,1,3)*INDEX(Datos!$B$3:$K$12,($A19+1)+-1,(D$15+1)+1)+INDEX(Kernels!$B$5:$D$7,2,1)*INDEX(Datos!$B$3:$K$12,($A19+1)+0,(D$15+1)+-1)+INDEX(Kernels!$B$5:$D$7,2,2)*INDEX(Datos!$B$3:$K$12,($A19+1)+0,(D$15+1)+0)+INDEX(Kernels!$B$5:$D$7,2,3)*INDEX(Datos!$B$3:$K$12,($A19+1)+0,(D$15+1)+1)+INDEX(Kernels!$B$5:$D$7,3,1)*INDEX(Datos!$B$3:$K$12,($A19+1)+1,(D$15+1)+-1)+INDEX(Kernels!$B$5:$D$7,3,2)*INDEX(Datos!$B$3:$K$12,($A19+1)+1,(D$15+1)+0)+INDEX(Kernels!$B$5:$D$7,3,3)*INDEX(Datos!$B$3:$K$12,($A19+1)+1,(D$15+1)+1))/Kernels!$F$6,"") -> 118.44444 | E19: =IF(AND($A19>=1,$A19<=8,E$15>=1,E$15<=8),(INDEX(Kernels!$B$5:$D$7,1,1)*INDEX(Datos!$B$3:$K$12,($A19+1)+-1,(E$15+1)+-1)+INDEX(Kernels!$B$5:$D$7,1,2)*INDEX(Datos!$B$3:$K$12,($A19+1)+-1,(E$15+1)+0)+INDEX(Kernels!$B$5:$D$7,1,3)*INDEX(Datos!$B$3:$K$12,($A19+1)+-1,(E$15+1)+1)+INDEX(Kernels!$B$5:$D$7,2,1)*INDEX(Datos!$B$3:$K$12,($A19+1)+0,(E$15+1)+-1)+INDEX(Kernels!$B$5:$D$7,2,2)*INDEX(Datos!$B$3:$K$12,($A19+1)+0,(E$15+1)+0)+INDEX(Kernels!$B$5:$D$7,2,3)*INDEX(Datos!$B$3:$K$12,($A19+1)+0,(E$15+1)+1)+INDEX(Kernels!$B$5:$D$7,3,1)*INDEX(Datos!$B$3:$K$12,($A19+1)+1,(E$15+1)+-1)+INDEX(Kernels!$B$5:$D$7,3,2)*INDEX(Datos!$B$3:$K$12,($A19+1)+1,(E$15+1)+0)+INDEX(Kernels!$B$5:$D$7,3,3)*INDEX(Datos!$B$3:$K$12,($A19+1)+1,(E$15+1)+1))/Kernels!$F$6,"") -> 102.11111 | F19: =IF(AND($A19>=1,$A19<=8,F$15>=1,F$15<=8),(INDEX(Kernels!$B$5:$D$7,1,1)*INDEX(Datos!$B$3:$K$12,($A19+1)+-1,(F$15+1)+-1)+INDEX(Kernels!$B$5:$D$7,1,2)*INDEX(Datos!$B$3:$K$12,($A19+1)+-1,(F$15+1)+0)+INDEX(Kernels!$B$5:$D$7,1,3)*INDEX(Datos!$B$3:$K$12,($A19+1)+-1,(F$15+1)+1)+INDEX(Kernels!$B$5:$D$7,2,1)*INDEX(Datos!$B$3:$K$12,($A19+1)+0,(F$15+1)+-1)+INDEX(Kernels!$B$5:$D$7,2,2)*INDEX(Datos!$B$3:$K$12,($A19+1)+0,(F$15+1)+0)+INDEX(Kernels!$B$5:$D$7,2,3)*INDEX(Datos!$B$3:$K$12,($A19+1)+0,(F$15+1)+1)+INDEX(Kernels!$B$5:$D$7,3,1)*INDEX(Datos!$B$3:$K$12,($A19+1)+1,(F$15+1)+-1)+INDEX(Kernels!$B$5:$D$7,3,2)*INDEX(Datos!$B$3:$K$12,($A19+1)+1,(F$15+1)+0)+INDEX(Kernels!$B$5:$D$7,3,3)*INDEX(Datos!$B$3:$K$12,($A19+1)+1,(F$15+1)+1))/Kernels!$F$6,"") -> 92 | G19: =IF(AND($A19>=1,$A19<=8,G$15>=1,G$15<=8),(INDEX(Kernels!$B$5:$D$7,1,1)*INDEX(Datos!$B$3:$K$12,($A19+1)+-1,(G$15+1)+-1)+INDEX(Kernels!$B$5:$D$7,1,2)*INDEX(Datos!$B$3:$K$12,($A19+1)+-1,(G$15+1)+0)+INDEX(Kernels!$B$5:$D$7,1,3)*INDEX(Datos!$B$3:$K$12,($A19+1)+-1,(G$15+1)+1)+INDEX(Kernels!$B$5:$D$7,2,1)*INDEX(Datos!$B$3:$K$12,($A19+1)+0,(G$15+1)+-1)+INDEX(Kernels!$B$5:$D$7,2,2)*INDEX(Datos!$B$3:$K$12,($A19+1)+0,(G$15+1)+0)+INDEX(Kernels!$B$5:$D$7,2,3)*INDEX(Datos!$B$3:$K$12,($A19+1)+0,(G$15+1)+1)+INDEX(Kernels!$B$5:$D$7,3,1)*INDEX(Datos!$B$3:$K$12,($A19+1)+1,(G$15+1)+-1)+INDEX(Kernels!$B$5:$D$7,3,2)*INDEX(Datos!$B$3:$K$12,($A19+1)+1,(G$15+1)+0)+INDEX(Kernels!$B$5:$D$7,3,3)*INDEX(Datos!$B$3:$K$12,($A19+1)+1,(G$15+1)+1))/Kernels!$F$6,"") -> 98.777778 | H19: =IF(AND($A19>=1,$A19<=8,H$15>=1,H$15<=8),(INDEX(Kernels!$B$5:$D$7,1,1)*INDEX(Datos!$B$3:$K$12,($A19+1)+-1,(H$15+1)+-1)+INDEX(Kernels!$B$5:$D$7,1,2)*INDEX(Datos!$B$3:$K$12,($A19+1)+-1,(H$15+1)+0)+INDEX(Kernels!$B$5:$D$7,1,3)*INDEX(Datos!$B$3:$K$12,($A19+1)+-1,(H$15+1)+1)+INDEX(Kernels!$B$5:$D$7,2,1)*INDEX(Datos!$B$3:$K$12,($A19+1)+0,(H$15+1)+-1)+INDEX(Kernels!$B$5:$D$7,2,2)*INDEX(Datos!$B$3:$K$12,($A19+1)+0,(H$15+1)+0)+INDEX(Kernels!$B$5:$D$7,2,3)*INDEX(Datos!$B$3:$K$12,($A19+1)+0,(H$15+1)+1)+INDEX(Kernels!$B$5:$D$7,3,1)*INDEX(Datos!$B$3:$K$12,($A19+1)+1,(H$15+1)+-1)+INDEX(Kernels!$B$5:$D$7,3,2)*INDEX(Datos!$B$3:$K$12,($A19+1)+1,(H$15+1)+0)+INDEX(Kernels!$B$5:$D$7,3,3)*INDEX(Datos!$B$3:$K$12,($A19+1)+1,(H$15+1)+1))/Kernels!$F$6,"") -> 115.22222 | I19: =IF(AND($A19>=1,$A19<=8,I$15>=1,I$15<=8),(INDEX(Kernels!$B$5:$D$7,1,1)*INDEX(Datos!$B$3:$K$12,($A19+1)+-1,(I$15+1)+-1)+INDEX(Kernels!$B$5:$D$7,1,2)*INDEX(Datos!$B$3:$K$12,($A19+1)+-1,(I$15+1)+0)+INDEX(Kernels!$B$5:$D$7,1,3)*INDEX(Datos!$B$3:$K$12,($A19+1)+-1,(I$15+1)+1)+INDEX(Kernels!$B$5:$D$7,2,1)*INDEX(Datos!$B$3:$K$12,($A19+1)+0,(I$15+1)+-1)+INDEX(Kernels!$B$5:$D$7,2,2)*INDEX(Datos!$B$3:$K$12,($A19+1)+0,(I$15+1)+0)+INDEX(Kernels!$B$5:$D$7,2,3)*INDEX(Datos!$B$3:$K$12,($A19+1)+0,(I$15+1)+1)+INDEX(Kernels!$B$5:$D$7,3,1)*INDEX(Datos!$B$3:$K$12,($A19+1)+1,(I$15+1)+-1)+INDEX(Kernels!$B$5:$D$7,3,2)*INDEX(Datos!$B$3:$K$12,($A19+1)+1,(I$15+1)+0)+INDEX(Kernels!$B$5:$D$7,3,3)*INDEX(Datos!$B$3:$K$12,($A19+1)+1,(I$15+1)+1))/Kernels!$F$6,"") -> 132.55556 | ... K19: =IF(AND($A19>=1,$A19<=8,K$15>=1,K$15<=8),(INDEX(Kernels!$B$5:$D$7,1,1)*INDEX(Datos!$B$3:$K$12,($A19+1)+-1,(K$15+1)+-1)+INDEX(Kernels!$B$5:$D$7,1,2)*INDEX(Datos!$B$3:$K$12,($A19+1)+-1,(K$15+1)+0)+INDEX(Kernels!$B$5:$D$7,1,3)*INDEX(Datos!$B$3:$K$12,($A19+1)+-1,(K$15+1)+1)+INDEX(Kernels!$B$5:$D$7,2,1)*INDEX(Datos!$B$3:$K$12,($A19+1)+0,(K$15+1)+-1)+INDEX(Kernels!$B$5:$D$7,2,2)*INDEX(Datos!$B$3:$K$12,($A19+1)+0,(K$15+1)+0)+INDEX(Kernels!$B$5:$D$7,2,3)*INDEX(Datos!$B$3:$K$12,($A19+1)+0,(K$15+1)+1)+INDEX(Kernels!$B$5:$D$7,3,1)*INDEX(Datos!$B$3:$K$12,($A19+1)+1,(K$15+1)+-1)+INDEX(Kernels!$B$5:$D$7,3,2)*INDEX(Datos!$B$3:$K$12,($A19+1)+1,(K$15+1)+0)+INDEX(Kernels!$B$5:$D$7,3,3)*INDEX(Datos!$B$3:$K$12,($A19+1)+1,(K$15+1)+1))/Kernels!$F$6,"")
A20: 4 | B20: =IF(AND($A20>=1,$A20<=8,B$15>=1,B$15<=8),(INDEX(Kernels!$B$5:$D$7,1,1)*INDEX(Datos!$B$3:$K$12,($A20+1)+-1,(B$15+1)+-1)+INDEX(Kernels!$B$5:$D$7,1,2)*INDEX(Datos!$B$3:$K$12,($A20+1)+-1,(B$15+1)+0)+INDEX(Kernels!$B$5:$D$7,1,3)*INDEX(Datos!$B$3:$K$12,($A20+1)+-1,(B$15+1)+1)+INDEX(Kernels!$B$5:$D$7,2,1)*INDEX(Datos!$B$3:$K$12,($A20+1)+0,(B$15+1)+-1)+INDEX(Kernels!$B$5:$D$7,2,2)*INDEX(Datos!$B$3:$K$12,($A20+1)+0,(B$15+1)+0)+INDEX(Kernels!$B$5:$D$7,2,3)*INDEX(Datos!$B$3:$K$12,($A20+1)+0,(B$15+1)+1)+INDEX(Kernels!$B$5:$D$7,3,1)*INDEX(Datos!$B$3:$K$12,($A20+1)+1,(B$15+1)+-1)+INDEX(Kernels!$B$5:$D$7,3,2)*INDEX(Datos!$B$3:$K$12,($A20+1)+1,(B$15+1)+0)+INDEX(Kernels!$B$5:$D$7,3,3)*INDEX(Datos!$B$3:$K$12,($A20+1)+1,(B$15+1)+1))/Kernels!$F$6,"") | C20: =IF(AND($A20>=1,$A20<=8,C$15>=1,C$15<=8),(INDEX(Kernels!$B$5:$D$7,1,1)*INDEX(Datos!$B$3:$K$12,($A20+1)+-1,(C$15+1)+-1)+INDEX(Kernels!$B$5:$D$7,1,2)*INDEX(Datos!$B$3:$K$12,($A20+1)+-1,(C$15+1)+0)+INDEX(Kernels!$B$5:$D$7,1,3)*INDEX(Datos!$B$3:$K$12,($A20+1)+-1,(C$15+1)+1)+INDEX(Kernels!$B$5:$D$7,2,1)*INDEX(Datos!$B$3:$K$12,($A20+1)+0,(C$15+1)+-1)+INDEX(Kernels!$B$5:$D$7,2,2)*INDEX(Datos!$B$3:$K$12,($A20+1)+0,(C$15+1)+0)+INDEX(Kernels!$B$5:$D$7,2,3)*INDEX(Datos!$B$3:$K$12,($A20+1)+0,(C$15+1)+1)+INDEX(Kernels!$B$5:$D$7,3,1)*INDEX(Datos!$B$3:$K$12,($A20+1)+1,(C$15+1)+-1)+INDEX(Kernels!$B$5:$D$7,3,2)*INDEX(Datos!$B$3:$K$12,($A20+1)+1,(C$15+1)+0)+INDEX(Kernels!$B$5:$D$7,3,3)*INDEX(Datos!$B$3:$K$12,($A20+1)+1,(C$15+1)+1))/Kernels!$F$6,"") -> 117.66667 | D20: =IF(AND($A20>=1,$A20<=8,D$15>=1,D$15<=8),(INDEX(Kernels!$B$5:$D$7,1,1)*INDEX(Datos!$B$3:$K$12,($A20+1)+-1,(D$15+1)+-1)+INDEX(Kernels!$B$5:$D$7,1,2)*INDEX(Datos!$B$3:$K$12,($A20+1)+-1,(D$15+1)+0)+INDEX(Kernels!$B$5:$D$7,1,3)*INDEX(Datos!$B$3:$K$12,($A20+1)+-1,(D$15+1)+1)+INDEX(Kernels!$B$5:$D$7,2,1)*INDEX(Datos!$B$3:$K$12,($A20+1)+0,(D$15+1)+-1)+INDEX(Kernels!$B$5:$D$7,2,2)*INDEX(Datos!$B$3:$K$12,($A20+1)+0,(D$15+1)+0)+INDEX(Kernels!$B$5:$D$7,2,3)*INDEX(Datos!$B$3:$K$12,($A20+1)+0,(D$15+1)+1)+INDEX(Kernels!$B$5:$D$7,3,1)*INDEX(Datos!$B$3:$K$12,($A20+1)+1,(D$15+1)+-1)+INDEX(Kernels!$B$5:$D$7,3,2)*INDEX(Datos!$B$3:$K$12,($A20+1)+1,(D$15+1)+0)+INDEX(Kernels!$B$5:$D$7,3,3)*INDEX(Datos!$B$3:$K$12,($A20+1)+1,(D$15+1)+1))/Kernels!$F$6,"") -> 107.55556 | E20: =IF(AND($A20>=1,$A20<=8,E$15>=1,E$15<=8),(INDEX(Kernels!$B$5:$D$7,1,1)*INDEX(Datos!$B$3:$K$12,($A20+1)+-1,(E$15+1)+-1)+INDEX(Kernels!$B$5:$D$7,1,2)*INDEX(Datos!$B$3:$K$12,($A20+1)+-1,(E$15+1)+0)+INDEX(Kernels!$B$5:$D$7,1,3)*INDEX(Datos!$B$3:$K$12,($A20+1)+-1,(E$15+1)+1)+INDEX(Kernels!$B$5:$D$7,2,1)*INDEX(Datos!$B$3:$K$12,($A20+1)+0,(E$15+1)+-1)+INDEX(Kernels!$B$5:$D$7,2,2)*INDEX(Datos!$B$3:$K$12,($A20+1)+0,(E$15+1)+0)+INDEX(Kernels!$B$5:$D$7,2,3)*INDEX(Datos!$B$3:$K$12,($A20+1)+0,(E$15+1)+1)+INDEX(Kernels!$B$5:$D$7,3,1)*INDEX(Datos!$B$3:$K$12,($A20+1)+1,(E$15+1)+-1)+INDEX(Kernels!$B$5:$D$7,3,2)*INDEX(Datos!$B$3:$K$12,($A20+1)+1,(E$15+1)+0)+INDEX(Kernels!$B$5:$D$7,3,3)*INDEX(Datos!$B$3:$K$12,($A20+1)+1,(E$15+1)+1))/Kernels!$F$6,"") -> 95 | F20: =IF(AND($A20>=1,$A20<=8,F$15>=1,F$15<=8),(INDEX(Kernels!$B$5:$D$7,1,1)*INDEX(Datos!$B$3:$K$12,($A20+1)+-1,(F$15+1)+-1)+INDEX(Kernels!$B$5:$D$7,1,2)*INDEX(Datos!$B$3:$K$12,($A20+1)+-1,(F$15+1)+0)+INDEX(Kernels!$B$5:$D$7,1,3)*INDEX(Datos!$B$3:$K$12,($A20+1)+-1,(F$15+1)+1)+INDEX(Kernels!$B$5:$D$7,2,1)*INDEX(Datos!$B$3:$K$12,($A20+1)+0,(F$15+1)+-1)+INDEX(Kernels!$B$5:$D$7,2,2)*INDEX(Datos!$B$3:$K$12,($A20+1)+0,(F$15+1)+0)+INDEX(Kernels!$B$5:$D$7,2,3)*INDEX(Datos!$B$3:$K$12,($A20+1)+0,(F$15+1)+1)+INDEX(Kernels!$B$5:$D$7,3,1)*INDEX(Datos!$B$3:$K$12,($A20+1)+1,(F$15+1)+-1)+INDEX(Kernels!$B$5:$D$7,3,2)*INDEX(Datos!$B$3:$K$12,($A20+1)+1,(F$15+1)+0)+INDEX(Kernels!$B$5:$D$7,3,3)*INDEX(Datos!$B$3:$K$12,($A20+1)+1,(F$15+1)+1))/Kernels!$F$6,"") -> 94 | G20: =IF(AND($A20>=1,$A20<=8,G$15>=1,G$15<=8),(INDEX(Kernels!$B$5:$D$7,1,1)*INDEX(Datos!$B$3:$K$12,($A20+1)+-1,(G$15+1)+-1)+INDEX(Kernels!$B$5:$D$7,1,2)*INDEX(Datos!$B$3:$K$12,($A20+1)+-1,(G$15+1)+0)+INDEX(Kernels!$B$5:$D$7,1,3)*INDEX(Datos!$B$3:$K$12,($A20+1)+-1,(G$15+1)+1)+INDEX(Kernels!$B$5:$D$7,2,1)*INDEX(Datos!$B$3:$K$12,($A20+1)+0,(G$15+1)+-1)+INDEX(Kernels!$B$5:$D$7,2,2)*INDEX(Datos!$B$3:$K$12,($A20+1)+0,(G$15+1)+0)+INDEX(Kernels!$B$5:$D$7,2,3)*INDEX(Datos!$B$3:$K$12,($A20+1)+0,(G$15+1)+1)+INDEX(Kernels!$B$5:$D$7,3,1)*INDEX(Datos!$B$3:$K$12,($A20+1)+1,(G$15+1)+-1)+INDEX(Kernels!$B$5:$D$7,3,2)*INDEX(Datos!$B$3:$K$12,($A20+1)+1,(G$15+1)+0)+INDEX(Kernels!$B$5:$D$7,3,3)*INDEX(Datos!$B$3:$K$12,($A20+1)+1,(G$15+1)+1))/Kernels!$F$6,"") -> 107.44444 | H20: =IF(AND($A20>=1,$A20<=8,H$15>=1,H$15<=8),(INDEX(Kernels!$B$5:$D$7,1,1)*INDEX(Datos!$B$3:$K$12,($A20+1)+-1,(H$15+1)+-1)+INDEX(Kernels!$B$5:$D$7,1,2)*INDEX(Datos!$B$3:$K$12,($A20+1)+-1,(H$15+1)+0)+INDEX(Kernels!$B$5:$D$7,1,3)*INDEX(Datos!$B$3:$K$12,($A20+1)+-1,(H$15+1)+1)+INDEX(Kernels!$B$5:$D$7,2,1)*INDEX(Datos!$B$3:$K$12,($A20+1)+0,(H$15+1)+-1)+INDEX(Kernels!$B$5:$D$7,2,2)*INDEX(Datos!$B$3:$K$12,($A20+1)+0,(H$15+1)+0)+INDEX(Kernels!$B$5:$D$7,2,3)*INDEX(Datos!$B$3:$K$12,($A20+1)+0,(H$15+1)+1)+INDEX(Kernels!$B$5:$D$7,3,1)*INDEX(Datos!$B$3:$K$12,($A20+1)+1,(H$15+1)+-1)+INDEX(Kernels!$B$5:$D$7,3,2)*INDEX(Datos!$B$3:$K$12,($A20+1)+1,(H$15+1)+0)+INDEX(Kernels!$B$5:$D$7,3,3)*INDEX(Datos!$B$3:$K$12,($A20+1)+1,(H$15+1)+1))/Kernels!$F$6,"") -> 123.77778 | I20: =IF(AND($A20>=1,$A20<=8,I$15>=1,I$15<=8),(INDEX(Kernels!$B$5:$D$7,1,1)*INDEX(Datos!$B$3:$K$12,($A20+1)+-1,(I$15+1)+-1)+INDEX(Kernels!$B$5:$D$7,1,2)*INDEX(Datos!$B$3:$K$12,($A20+1)+-1,(I$15+1)+0)+INDEX(Kernels!$B$5:$D$7,1,3)*INDEX(Datos!$B$3:$K$12,($A20+1)+-1,(I$15+1)+1)+INDEX(Kernels!$B$5:$D$7,2,1)*INDEX(Datos!$B$3:$K$12,($A20+1)+0,(I$15+1)+-1)+INDEX(Kernels!$B$5:$D$7,2,2)*INDEX(Datos!$B$3:$K$12,($A20+1)+0,(I$15+1)+0)+INDEX(Kernels!$B$5:$D$7,2,3)*INDEX(Datos!$B$3:$K$12,($A20+1)+0,(I$15+1)+1)+INDEX(Kernels!$B$5:$D$7,3,1)*INDEX(Datos!$B$3:$K$12,($A20+1)+1,(I$15+1)+-1)+INDEX(Kernels!$B$5:$D$7,3,2)*INDEX(Datos!$B$3:$K$12,($A20+1)+1,(I$15+1)+0)+INDEX(Kernels!$B$5:$D$7,3,3)*INDEX(Datos!$B$3:$K$12,($A20+1)+1,(I$15+1)+1))/Kernels!$F$6,"") -> 138.55556 | ... K20: =IF(AND($A20>=1,$A20<=8,K$15>=1,K$15<=8),(INDEX(Kernels!$B$5:$D$7,1,1)*INDEX(Datos!$B$3:$K$12,($A20+1)+-1,(K$15+1)+-1)+INDEX(Kernels!$B$5:$D$7,1,2)*INDEX(Datos!$B$3:$K$12,($A20+1)+-1,(K$15+1)+0)+INDEX(Kernels!$B$5:$D$7,1,3)*INDEX(Datos!$B$3:$K$12,($A20+1)+-1,(K$15+1)+1)+INDEX(Kernels!$B$5:$D$7,2,1)*INDEX(Datos!$B$3:$K$12,($A20+1)+0,(K$15+1)+-1)+INDEX(Kernels!$B$5:$D$7,2,2)*INDEX(Datos!$B$3:$K$12,($A20+1)+0,(K$15+1)+0)+INDEX(Kernels!$B$5:$D$7,2,3)*INDEX(Datos!$B$3:$K$12,($A20+1)+0,(K$15+1)+1)+INDEX(Kernels!$B$5:$D$7,3,1)*INDEX(Datos!$B$3:$K$12,($A20+1)+1,(K$15+1)+-1)+INDEX(Kernels!$B$5:$D$7,3,2)*INDEX(Datos!$B$3:$K$12,($A20+1)+1,(K$15+1)+0)+INDEX(Kernels!$B$5:$D$7,3,3)*INDEX(Datos!$B$3:$K$12,($A20+1)+1,(K$15+1)+1))/Kernels!$F$6,"")
A21: 5 | B21: =IF(AND($A21>=1,$A21<=8,B$15>=1,B$15<=8),(INDEX(Kernels!$B$5:$D$7,1,1)*INDEX(Datos!$B$3:$K$12,($A21+1)+-1,(B$15+1)+-1)+INDEX(Kernels!$B$5:$D$7,1,2)*INDEX(Datos!$B$3:$K$12,($A21+1)+-1,(B$15+1)+0)+INDEX(Kernels!$B$5:$D$7,1,3)*INDEX(Datos!$B$3:$K$12,($A21+1)+-1,(B$15+1)+1)+INDEX(Kernels!$B$5:$D$7,2,1)*INDEX(Datos!$B$3:$K$12,($A21+1)+0,(B$15+1)+-1)+INDEX(Kernels!$B$5:$D$7,2,2)*INDEX(Datos!$B$3:$K$12,($A21+1)+0,(B$15+1)+0)+INDEX(Kernels!$B$5:$D$7,2,3)*INDEX(Datos!$B$3:$K$12,($A21+1)+0,(B$15+1)+1)+INDEX(Kernels!$B$5:$D$7,3,1)*INDEX(Datos!$B$3:$K$12,($A21+1)+1,(B$15+1)+-1)+INDEX(Kernels!$B$5:$D$7,3,2)*INDEX(Datos!$B$3:$K$12,($A21+1)+1,(B$15+1)+0)+INDEX(Kernels!$B$5:$D$7,3,3)*INDEX(Datos!$B$3:$K$12,($A21+1)+1,(B$15+1)+1))/Kernels!$F$6,"") | C21: =IF(AND($A21>=1,$A21<=8,C$15>=1,C$15<=8),(INDEX(Kernels!$B$5:$D$7,1,1)*INDEX(Datos!$B$3:$K$12,($A21+1)+-1,(C$15+1)+-1)+INDEX(Kernels!$B$5:$D$7,1,2)*INDEX(Datos!$B$3:$K$12,($A21+1)+-1,(C$15+1)+0)+INDEX(Kernels!$B$5:$D$7,1,3)*INDEX(Datos!$B$3:$K$12,($A21+1)+-1,(C$15+1)+1)+INDEX(Kernels!$B$5:$D$7,2,1)*INDEX(Datos!$B$3:$K$12,($A21+1)+0,(C$15+1)+-1)+INDEX(Kernels!$B$5:$D$7,2,2)*INDEX(Datos!$B$3:$K$12,($A21+1)+0,(C$15+1)+0)+INDEX(Kernels!$B$5:$D$7,2,3)*INDEX(Datos!$B$3:$K$12,($A21+1)+0,(C$15+1)+1)+INDEX(Kernels!$B$5:$D$7,3,1)*INDEX(Datos!$B$3:$K$12,($A21+1)+1,(C$15+1)+-1)+INDEX(Kernels!$B$5:$D$7,3,2)*INDEX(Datos!$B$3:$K$12,($A21+1)+1,(C$15+1)+0)+INDEX(Kernels!$B$5:$D$7,3,3)*INDEX(Datos!$B$3:$K$12,($A21+1)+1,(C$15+1)+1))/Kernels!$F$6,"") -> 98.444444 | D21: =IF(AND($A21>=1,$A21<=8,D$15>=1,D$15<=8),(INDEX(Kernels!$B$5:$D$7,1,1)*INDEX(Datos!$B$3:$K$12,($A21+1)+-1,(D$15+1)+-1)+INDEX(Kernels!$B$5:$D$7,1,2)*INDEX(Datos!$B$3:$K$12,($A21+1)+-1,(D$15+1)+0)+INDEX(Kernels!$B$5:$D$7,1,3)*INDEX(Datos!$B$3:$K$12,($A21+1)+-1,(D$15+1)+1)+INDEX(Kernels!$B$5:$D$7,2,1)*INDEX(Datos!$B$3:$K$12,($A21+1)+0,(D$15+1)+-1)+INDEX(Kernels!$B$5:$D$7,2,2)*INDEX(Datos!$B$3:$K$12,($A21+1)+0,(D$15+1)+0)+INDEX(Kernels!$B$5:$D$7,2,3)*INDEX(Datos!$B$3:$K$12,($A21+1)+0,(D$15+1)+1)+INDEX(Kernels!$B$5:$D$7,3,1)*INDEX(Datos!$B$3:$K$12,($A21+1)+1,(D$15+1)+-1)+INDEX(Kernels!$B$5:$D$7,3,2)*INDEX(Datos!$B$3:$K$12,($A21+1)+1,(D$15+1)+0)+INDEX(Kernels!$B$5:$D$7,3,3)*INDEX(Datos!$B$3:$K$12,($A21+1)+1,(D$15+1)+1))/Kernels!$F$6,"") -> 93.333333 | E21: =IF(AND($A21>=1,$A21<=8,E$15>=1,E$15<=8),(INDEX(Kernels!$B$5:$D$7,1,1)*INDEX(Datos!$B$3:$K$12,($A21+1)+-1,(E$15+1)+-1)+INDEX(Kernels!$B$5:$D$7,1,2)*INDEX(Datos!$B$3:$K$12,($A21+1)+-1,(E$15+1)+0)+INDEX(Kernels!$B$5:$D$7,1,3)*INDEX(Datos!$B$3:$K$12,($A21+1)+-1,(E$15+1)+1)+INDEX(Kernels!$B$5:$D$7,2,1)*INDEX(Datos!$B$3:$K$12,($A21+1)+0,(E$15+1)+-1)+INDEX(Kernels!$B$5:$D$7,2,2)*INDEX(Datos!$B$3:$K$12,($A21+1)+0,(E$15+1)+0)+INDEX(Kernels!$B$5:$D$7,2,3)*INDEX(Datos!$B$3:$K$12,($A21+1)+0,(E$15+1)+1)+INDEX(Kernels!$B$5:$D$7,3,1)*INDEX(Datos!$B$3:$K$12,($A21+1)+1,(E$15+1)+-1)+INDEX(Kernels!$B$5:$D$7,3,2)*INDEX(Datos!$B$3:$K$12,($A21+1)+1,(E$15+1)+0)+INDEX(Kernels!$B$5:$D$7,3,3)*INDEX(Datos!$B$3:$K$12,($A21+1)+1,(E$15+1)+1))/Kernels!$F$6,"") -> 93.555556 | F21: =IF(AND($A21>=1,$A21<=8,F$15>=1,F$15<=8),(INDEX(Kernels!$B$5:$D$7,1,1)*INDEX(Datos!$B$3:$K$12,($A21+1)+-1,(F$15+1)+-1)+INDEX(Kernels!$B$5:$D$7,1,2)*INDEX(Datos!$B$3:$K$12,($A21+1)+-1,(F$15+1)+0)+INDEX(Kernels!$B$5:$D$7,1,3)*INDEX(Datos!$B$3:$K$12,($A21+1)+-1,(F$15+1)+1)+INDEX(Kernels!$B$5:$D$7,2,1)*INDEX(Datos!$B$3:$K$12,($A21+1)+0,(F$15+1)+-1)+INDEX(Kernels!$B$5:$D$7,2,2)*INDEX(Datos!$B$3:$K$12,($A21+1)+0,(F$15+1)+0)+INDEX(Kernels!$B$5:$D$7,2,3)*INDEX(Datos!$B$3:$K$12,($A21+1)+0,(F$15+1)+1)+INDEX(Kernels!$B$5:$D$7,3,1)*INDEX(Datos!$B$3:$K$12,($A21+1)+1,(F$15+1)+-1)+INDEX(Kernels!$B$5:$D$7,3,2)*INDEX(Datos!$B$3:$K$12,($A21+1)+1,(F$15+1)+0)+INDEX(Kernels!$B$5:$D$7,3,3)*INDEX(Datos!$B$3:$K$12,($A21+1)+1,(F$15+1)+1))/Kernels!$F$6,"") -> 102.44444 | G21: =IF(AND($A21>=1,$A21<=8,G$15>=1,G$15<=8),(INDEX(Kernels!$B$5:$D$7,1,1)*INDEX(Datos!$B$3:$K$12,($A21+1)+-1,(G$15+1)+-1)+INDEX(Kernels!$B$5:$D$7,1,2)*INDEX(Datos!$B$3:$K$12,($A21+1)+-1,(G$15+1)+0)+INDEX(Kernels!$B$5:$D$7,1,3)*INDEX(Datos!$B$3:$K$12,($A21+1)+-1,(G$15+1)+1)+INDEX(Kernels!$B$5:$D$7,2,1)*INDEX(Datos!$B$3:$K$12,($A21+1)+0,(G$15+1)+-1)+INDEX(Kernels!$B$5:$D$7,2,2)*INDEX(Datos!$B$3:$K$12,($A21+1)+0,(G$15+1)+0)+INDEX(Kernels!$B$5:$D$7,2,3)*INDEX(Datos!$B$3:$K$12,($A21+1)+0,(G$15+1)+1)+INDEX(Kernels!$B$5:$D$7,3,1)*INDEX(Datos!$B$3:$K$12,($A21+1)+1,(G$15+1)+-1)+INDEX(Kernels!$B$5:$D$7,3,2)*INDEX(Datos!$B$3:$K$12,($A21+1)+1,(G$15+1)+0)+INDEX(Kernels!$B$5:$D$7,3,3)*INDEX(Datos!$B$3:$K$12,($A21+1)+1,(G$15+1)+1))/Kernels!$F$6,"") -> 116.44444 | H21: =IF(AND($A21>=1,$A21<=8,H$15>=1,H$15<=8),(INDEX(Kernels!$B$5:$D$7,1,1)*INDEX(Datos!$B$3:$K$12,($A21+1)+-1,(H$15+1)+-1)+INDEX(Kernels!$B$5:$D$7,1,2)*INDEX(Datos!$B$3:$K$12,($A21+1)+-1,(H$15+1)+0)+INDEX(Kernels!$B$5:$D$7,1,3)*INDEX(Datos!$B$3:$K$12,($A21+1)+-1,(H$15+1)+1)+INDEX(Kernels!$B$5:$D$7,2,1)*INDEX(Datos!$B$3:$K$12,($A21+1)+0,(H$15+1)+-1)+INDEX(Kernels!$B$5:$D$7,2,2)*INDEX(Datos!$B$3:$K$12,($A21+1)+0,(H$15+1)+0)+INDEX(Kernels!$B$5:$D$7,2,3)*INDEX(Datos!$B$3:$K$12,($A21+1)+0,(H$15+1)+1)+INDEX(Kernels!$B$5:$D$7,3,1)*INDEX(Datos!$B$3:$K$12,($A21+1)+1,(H$15+1)+-1)+INDEX(Kernels!$B$5:$D$7,3,2)*INDEX(Datos!$B$3:$K$12,($A21+1)+1,(H$15+1)+0)+INDEX(Kernels!$B$5:$D$7,3,3)*INDEX(Datos!$B$3:$K$12,($A21+1)+1,(H$15+1)+1))/Kernels!$F$6,"") -> 128.44444 | I21: =IF(AND($A21>=1,$A21<=8,I$15>=1,I$15<=8),(INDEX(Kernels!$B$5:$D$7,1,1)*INDEX(Datos!$B$3:$K$12,($A21+1)+-1,(I$15+1)+-1)+INDEX(Kernels!$B$5:$D$7,1,2)*INDEX(Datos!$B$3:$K$12,($A21+1)+-1,(I$15+1)+0)+INDEX(Kernels!$B$5:$D$7,1,3)*INDEX(Datos!$B$3:$K$12,($A21+1)+-1,(I$15+1)+1)+INDEX(Kernels!$B$5:$D$7,2,1)*INDEX(Datos!$B$3:$K$12,($A21+1)+0,(I$15+1)+-1)+INDEX(Kernels!$B$5:$D$7,2,2)*INDEX(Datos!$B$3:$K$12,($A21+1)+0,(I$15+1)+0)+INDEX(Kernels!$B$5:$D$7,2,3)*INDEX(Datos!$B$3:$K$12,($A21+1)+0,(I$15+1)+1)+INDEX(Kernels!$B$5:$D$7,3,1)*INDEX(Datos!$B$3:$K$12,($A21+1)+1,(I$15+1)+-1)+INDEX(Kernels!$B$5:$D$7,3,2)*INDEX(Datos!$B$3:$K$12,($A21+1)+1,(I$15+1)+0)+INDEX(Kernels!$B$5:$D$7,3,3)*INDEX(Datos!$B$3:$K$12,($A21+1)+1,(I$15+1)+1))/Kernels!$F$6,"") -> 137 | ... K21: =IF(AND($A21>=1,$A21<=8,K$15>=1,K$15<=8),(INDEX(Kernels!$B$5:$D$7,1,1)*INDEX(Datos!$B$3:$K$12,($A21+1)+-1,(K$15+1)+-1)+INDEX(Kernels!$B$5:$D$7,1,2)*INDEX(Datos!$B$3:$K$12,($A21+1)+-1,(K$15+1)+0)+INDEX(Kernels!$B$5:$D$7,1,3)*INDEX(Datos!$B$3:$K$12,($A21+1)+-1,(K$15+1)+1)+INDEX(Kernels!$B$5:$D$7,2,1)*INDEX(Datos!$B$3:$K$12,($A21+1)+0,(K$15+1)+-1)+INDEX(Kernels!$B$5:$D$7,2,2)*INDEX(Datos!$B$3:$K$12,($A21+1)+0,(K$15+1)+0)+INDEX(Kernels!$B$5:$D$7,2,3)*INDEX(Datos!$B$3:$K$12,($A21+1)+0,(K$15+1)+1)+INDEX(Kernels!$B$5:$D$7,3,1)*INDEX(Datos!$B$3:$K$12,($A21+1)+1,(K$15+1)+-1)+INDEX(Kernels!$B$5:$D$7,3,2)*INDEX(Datos!$B$3:$K$12,($A21+1)+1,(K$15+1)+0)+INDEX(Kernels!$B$5:$D$7,3,3)*INDEX(Datos!$B$3:$K$12,($A21+1)+1,(K$15+1)+1))/Kernels!$F$6,"")
A22: 6 | B22: =IF(AND($A22>=1,$A22<=8,B$15>=1,B$15<=8),(INDEX(Kernels!$B$5:$D$7,1,1)*INDEX(Datos!$B$3:$K$12,($A22+1)+-1,(B$15+1)+-1)+INDEX(Kernels!$B$5:$D$7,1,2)*INDEX(Datos!$B$3:$K$12,($A22+1)+-1,(B$15+1)+0)+INDEX(Kernels!$B$5:$D$7,1,3)*INDEX(Datos!$B$3:$K$12,($A22+1)+-1,(B$15+1)+1)+INDEX(Kernels!$B$5:$D$7,2,1)*INDEX(Datos!$B$3:$K$12,($A22+1)+0,(B$15+1)+-1)+INDEX(Kernels!$B$5:$D$7,2,2)*INDEX(Datos!$B$3:$K$12,($A22+1)+0,(B$15+1)+0)+INDEX(Kernels!$B$5:$D$7,2,3)*INDEX(Datos!$B$3:$K$12,($A22+1)+0,(B$15+1)+1)+INDEX(Kernels!$B$5:$D$7,3,1)*INDEX(Datos!$B$3:$K$12,($A22+1)+1,(B$15+1)+-1)+INDEX(Kernels!$B$5:$D$7,3,2)*INDEX(Datos!$B$3:$K$12,($A22+1)+1,(B$15+1)+0)+INDEX(Kernels!$B$5:$D$7,3,3)*INDEX(Datos!$B$3:$K$12,($A22+1)+1,(B$15+1)+1))/Kernels!$F$6,"") | C22: =IF(AND($A22>=1,$A22<=8,C$15>=1,C$15<=8),(INDEX(Kernels!$B$5:$D$7,1,1)*INDEX(Datos!$B$3:$K$12,($A22+1)+-1,(C$15+1)+-1)+INDEX(Kernels!$B$5:$D$7,1,2)*INDEX(Datos!$B$3:$K$12,($A22+1)+-1,(C$15+1)+0)+INDEX(Kernels!$B$5:$D$7,1,3)*INDEX(Datos!$B$3:$K$12,($A22+1)+-1,(C$15+1)+1)+INDEX(Kernels!$B$5:$D$7,2,1)*INDEX(Datos!$B$3:$K$12,($A22+1)+0,(C$15+1)+-1)+INDEX(Kernels!$B$5:$D$7,2,2)*INDEX(Datos!$B$3:$K$12,($A22+1)+0,(C$15+1)+0)+INDEX(Kernels!$B$5:$D$7,2,3)*INDEX(Datos!$B$3:$K$12,($A22+1)+0,(C$15+1)+1)+INDEX(Kernels!$B$5:$D$7,3,1)*INDEX(Datos!$B$3:$K$12,($A22+1)+1,(C$15+1)+-1)+INDEX(Kernels!$B$5:$D$7,3,2)*INDEX(Datos!$B$3:$K$12,($A22+1)+1,(C$15+1)+0)+INDEX(Kernels!$B$5:$D$7,3,3)*INDEX(Datos!$B$3:$K$12,($A22+1)+1,(C$15+1)+1))/Kernels!$F$6,"") -> 79.444444 | D22: =IF(AND($A22>=1,$A22<=8,D$15>=1,D$15<=8),(INDEX(Kernels!$B$5:$D$7,1,1)*INDEX(Datos!$B$3:$K$12,($A22+1)+-1,(D$15+1)+-1)+INDEX(Kernels!$B$5:$D$7,1,2)*INDEX(Datos!$B$3:$K$12,($A22+1)+-1,(D$15+1)+0)+INDEX(Kernels!$B$5:$D$7,1,3)*INDEX(Datos!$B$3:$K$12,($A22+1)+-1,(D$15+1)+1)+INDEX(Kernels!$B$5:$D$7,2,1)*INDEX(Datos!$B$3:$K$12,($A22+1)+0,(D$15+1)+-1)+INDEX(Kernels!$B$5:$D$7,2,2)*INDEX(Datos!$B$3:$K$12,($A22+1)+0,(D$15+1)+0)+INDEX(Kernels!$B$5:$D$7,2,3)*INDEX(Datos!$B$3:$K$12,($A22+1)+0,(D$15+1)+1)+INDEX(Kernels!$B$5:$D$7,3,1)*INDEX(Datos!$B$3:$K$12,($A22+1)+1,(D$15+1)+-1)+INDEX(Kernels!$B$5:$D$7,3,2)*INDEX(Datos!$B$3:$K$12,($A22+1)+1,(D$15+1)+0)+INDEX(Kernels!$B$5:$D$7,3,3)*INDEX(Datos!$B$3:$K$12,($A22+1)+1,(D$15+1)+1))/Kernels!$F$6,"") -> 85.777778 | E22: =IF(AND($A22>=1,$A22<=8,E$15>=1,E$15<=8),(INDEX(Kernels!$B$5:$D$7,1,1)*INDEX(Datos!$B$3:$K$12,($A22+1)+-1,(E$15+1)+-1)+INDEX(Kernels!$B$5:$D$7,1,2)*INDEX(Datos!$B$3:$K$12,($A22+1)+-1,(E$15+1)+0)+INDEX(Kernels!$B$5:$D$7,1,3)*INDEX(Datos!$B$3:$K$12,($A22+1)+-1,(E$15+1)+1)+INDEX(Kernels!$B$5:$D$7,2,1)*INDEX(Datos!$B$3:$K$12,($A22+1)+0,(E$15+1)+-1)+INDEX(Kernels!$B$5:$D$7,2,2)*INDEX(Datos!$B$3:$K$12,($A22+1)+0,(E$15+1)+0)+INDEX(Kernels!$B$5:$D$7,2,3)*INDEX(Datos!$B$3:$K$12,($A22+1)+0,(E$15+1)+1)+INDEX(Kernels!$B$5:$D$7,3,1)*INDEX(Datos!$B$3:$K$12,($A22+1)+1,(E$15+1)+-1)+INDEX(Kernels!$B$5:$D$7,3,2)*INDEX(Datos!$B$3:$K$12,($A22+1)+1,(E$15+1)+0)+INDEX(Kernels!$B$5:$D$7,3,3)*INDEX(Datos!$B$3:$K$12,($A22+1)+1,(E$15+1)+1))/Kernels!$F$6,"") -> 99.222222 | F22: =IF(AND($A22>=1,$A22<=8,F$15>=1,F$15<=8),(INDEX(Kernels!$B$5:$D$7,1,1)*INDEX(Datos!$B$3:$K$12,($A22+1)+-1,(F$15+1)+-1)+INDEX(Kernels!$B$5:$D$7,1,2)*INDEX(Datos!$B$3:$K$12,($A22+1)+-1,(F$15+1)+0)+INDEX(Kernels!$B$5:$D$7,1,3)*INDEX(Datos!$B$3:$K$12,($A22+1)+-1,(F$15+1)+1)+INDEX(Kernels!$B$5:$D$7,2,1)*INDEX(Datos!$B$3:$K$12,($A22+1)+0,(F$15+1)+-1)+INDEX(Kernels!$B$5:$D$7,2,2)*INDEX(Datos!$B$3:$K$12,($A22+1)+0,(F$15+1)+0)+INDEX(Kernels!$B$5:$D$7,2,3)*INDEX(Datos!$B$3:$K$12,($A22+1)+0,(F$15+1)+1)+INDEX(Kernels!$B$5:$D$7,3,1)*INDEX(Datos!$B$3:$K$12,($A22+1)+1,(F$15+1)+-1)+INDEX(Kernels!$B$5:$D$7,3,2)*INDEX(Datos!$B$3:$K$12,($A22+1)+1,(F$15+1)+0)+INDEX(Kernels!$B$5:$D$7,3,3)*INDEX(Datos!$B$3:$K$12,($A22+1)+1,(F$15+1)+1))/Kernels!$F$6,"") -> 111.44444 | G22: =IF(AND($A22>=1,$A22<=8,G$15>=1,G$15<=8),(INDEX(Kernels!$B$5:$D$7,1,1)*INDEX(Datos!$B$3:$K$12,($A22+1)+-1,(G$15+1)+-1)+INDEX(Kernels!$B$5:$D$7,1,2)*INDEX(Datos!$B$3:$K$12,($A22+1)+-1,(G$15+1)+0)+INDEX(Kernels!$B$5:$D$7,1,3)*INDEX(Datos!$B$3:$K$12,($A22+1)+-1,(G$15+1)+1)+INDEX(Kernels!$B$5:$D$7,2,1)*INDEX(Datos!$B$3:$K$12,($A22+1)+0,(G$15+1)+-1)+INDEX(Kernels!$B$5:$D$7,2,2)*INDEX(Datos!$B$3:$K$12,($A22+1)+0,(G$15+1)+0)+INDEX(Kernels!$B$5:$D$7,2,3)*INDEX(Datos!$B$3:$K$12,($A22+1)+0,(G$15+1)+1)+INDEX(Kernels!$B$5:$D$7,3,1)*INDEX(Datos!$B$3:$K$12,($A22+1)+1,(G$15+1)+-1)+INDEX(Kernels!$B$5:$D$7,3,2)*INDEX(Datos!$B$3:$K$12,($A22+1)+1,(G$15+1)+0)+INDEX(Kernels!$B$5:$D$7,3,3)*INDEX(Datos!$B$3:$K$12,($A22+1)+1,(G$15+1)+1))/Kernels!$F$6,"") -> 119 | H22: =IF(AND($A22>=1,$A22<=8,H$15>=1,H$15<=8),(INDEX(Kernels!$B$5:$D$7,1,1)*INDEX(Datos!$B$3:$K$12,($A22+1)+-1,(H$15+1)+-1)+INDEX(Kernels!$B$5:$D$7,1,2)*INDEX(Datos!$B$3:$K$12,($A22+1)+-1,(H$15+1)+0)+INDEX(Kernels!$B$5:$D$7,1,3)*INDEX(Datos!$B$3:$K$12,($A22+1)+-1,(H$15+1)+1)+INDEX(Kernels!$B$5:$D$7,2,1)*INDEX(Datos!$B$3:$K$12,($A22+1)+0,(H$15+1)+-1)+INDEX(Kernels!$B$5:$D$7,2,2)*INDEX(Datos!$B$3:$K$12,($A22+1)+0,(H$15+1)+0)+INDEX(Kernels!$B$5:$D$7,2,3)*INDEX(Datos!$B$3:$K$12,($A22+1)+0,(H$15+1)+1)+INDEX(Kernels!$B$5:$D$7,3,1)*INDEX(Datos!$B$3:$K$12,($A22+1)+1,(H$15+1)+-1)+INDEX(Kernels!$B$5:$D$7,3,2)*INDEX(Datos!$B$3:$K$12,($A22+1)+1,(H$15+1)+0)+INDEX(Kernels!$B$5:$D$7,3,3)*INDEX(Datos!$B$3:$K$12,($A22+1)+1,(H$15+1)+1))/Kernels!$F$6,"") -> 125.88889 | I22: =IF(AND($A22>=1,$A22<=8,I$15>=1,I$15<=8),(INDEX(Kernels!$B$5:$D$7,1,1)*INDEX(Datos!$B$3:$K$12,($A22+1)+-1,(I$15+1)+-1)+INDEX(Kernels!$B$5:$D$7,1,2)*INDEX(Datos!$B$3:$K$12,($A22+1)+-1,(I$15+1)+0)+INDEX(Kernels!$B$5:$D$7,1,3)*INDEX(Datos!$B$3:$K$12,($A22+1)+-1,(I$15+1)+1)+INDEX(Kernels!$B$5:$D$7,2,1)*INDEX(Datos!$B$3:$K$12,($A22+1)+0,(I$15+1)+-1)+INDEX(Kernels!$B$5:$D$7,2,2)*INDEX(Datos!$B$3:$K$12,($A22+1)+0,(I$15+1)+0)+INDEX(Kernels!$B$5:$D$7,2,3)*INDEX(Datos!$B$3:$K$12,($A22+1)+0,(I$15+1)+1)+INDEX(Kernels!$B$5:$D$7,3,1)*INDEX(Datos!$B$3:$K$12,($A22+1)+1,(I$15+1)+-1)+INDEX(Kernels!$B$5:$D$7,3,2)*INDEX(Datos!$B$3:$K$12,($A22+1)+1,(I$15+1)+0)+INDEX(Kernels!$B$5:$D$7,3,3)*INDEX(Datos!$B$3:$K$12,($A22+1)+1,(I$15+1)+1))/Kernels!$F$6,"") -> 132.22222 | ... K22: =IF(AND($A22>=1,$A22<=8,K$15>=1,K$15<=8),(INDEX(Kernels!$B$5:$D$7,1,1)*INDEX(Datos!$B$3:$K$12,($A22+1)+-1,(K$15+1)+-1)+INDEX(Kernels!$B$5:$D$7,1,2)*INDEX(Datos!$B$3:$K$12,($A22+1)+-1,(K$15+1)+0)+INDEX(Kernels!$B$5:$D$7,1,3)*INDEX(Datos!$B$3:$K$12,($A22+1)+-1,(K$15+1)+1)+INDEX(Kernels!$B$5:$D$7,2,1)*INDEX(Datos!$B$3:$K$12,($A22+1)+0,(K$15+1)+-1)+INDEX(Kernels!$B$5:$D$7,2,2)*INDEX(Datos!$B$3:$K$12,($A22+1)+0,(K$15+1)+0)+INDEX(Kernels!$B$5:$D$7,2,3)*INDEX(Datos!$B$3:$K$12,($A22+1)+0,(K$15+1)+1)+INDEX(Kernels!$B$5:$D$7,3,1)*INDEX(Datos!$B$3:$K$12,($A22+1)+1,(K$15+1)+-1)+INDEX(Kernels!$B$5:$D$7,3,2)*INDEX(Datos!$B$3:$K$12,($A22+1)+1,(K$15+1)+0)+INDEX(Kernels!$B$5:$D$7,3,3)*INDEX(Datos!$B$3:$K$12,($A22+1)+1,(K$15+1)+1))/Kernels!$F$6,"")
A23: 7 | B23: =IF(AND($A23>=1,$A23<=8,B$15>=1,B$15<=8),(INDEX(Kernels!$B$5:$D$7,1,1)*INDEX(Datos!$B$3:$K$12,($A23+1)+-1,(B$15+1)+-1)+INDEX(Kernels!$B$5:$D$7,1,2)*INDEX(Datos!$B$3:$K$12,($A23+1)+-1,(B$15+1)+0)+INDEX(Kernels!$B$5:$D$7,1,3)*INDEX(Datos!$B$3:$K$12,($A23+1)+-1,(B$15+1)+1)+INDEX(Kernels!$B$5:$D$7,2,1)*INDEX(Datos!$B$3:$K$12,($A23+1)+0,(B$15+1)+-1)+INDEX(Kernels!$B$5:$D$7,2,2)*INDEX(Datos!$B$3:$K$12,($A23+1)+0,(B$15+1)+0)+INDEX(Kernels!$B$5:$D$7,2,3)*INDEX(Datos!$B$3:$K$12,($A23+1)+0,(B$15+1)+1)+INDEX(Kernels!$B$5:$D$7,3,1)*INDEX(Datos!$B$3:$K$12,($A23+1)+1,(B$15+1)+-1)+INDEX(Kernels!$B$5:$D$7,3,2)*INDEX(Datos!$B$3:$K$12,($A23+1)+1,(B$15+1)+0)+INDEX(Kernels!$B$5:$D$7,3,3)*INDEX(Datos!$B$3:$K$12,($A23+1)+1,(B$15+1)+1))/Kernels!$F$6,"") | C23: =IF(AND($A23>=1,$A23<=8,C$15>=1,C$15<=8),(INDEX(Kernels!$B$5:$D$7,1,1)*INDEX(Datos!$B$3:$K$12,($A23+1)+-1,(C$15+1)+-1)+INDEX(Kernels!$B$5:$D$7,1,2)*INDEX(Datos!$B$3:$K$12,($A23+1)+-1,(C$15+1)+0)+INDEX(Kernels!$B$5:$D$7,1,3)*INDEX(Datos!$B$3:$K$12,($A23+1)+-1,(C$15+1)+1)+INDEX(Kernels!$B$5:$D$7,2,1)*INDEX(Datos!$B$3:$K$12,($A23+1)+0,(C$15+1)+-1)+INDEX(Kernels!$B$5:$D$7,2,2)*INDEX(Datos!$B$3:$K$12,($A23+1)+0,(C$15+1)+0)+INDEX(Kernels!$B$5:$D$7,2,3)*INDEX(Datos!$B$3:$K$12,($A23+1)+0,(C$15+1)+1)+INDEX(Kernels!$B$5:$D$7,3,1)*INDEX(Datos!$B$3:$K$12,($A23+1)+1,(C$15+1)+-1)+INDEX(Kernels!$B$5:$D$7,3,2)*INDEX(Datos!$B$3:$K$12,($A23+1)+1,(C$15+1)+0)+INDEX(Kernels!$B$5:$D$7,3,3)*INDEX(Datos!$B$3:$K$12,($A23+1)+1,(C$15+1)+1))/Kernels!$F$6,"") -> 68 | D23: =IF(AND($A23>=1,$A23<=8,D$15>=1,D$15<=8),(INDEX(Kernels!$B$5:$D$7,1,1)*INDEX(Datos!$B$3:$K$12,($A23+1)+-1,(D$15+1)+-1)+INDEX(Kernels!$B$5:$D$7,1,2)*INDEX(Datos!$B$3:$K$12,($A23+1)+-1,(D$15+1)+0)+INDEX(Kernels!$B$5:$D$7,1,3)*INDEX(Datos!$B$3:$K$12,($A23+1)+-1,(D$15+1)+1)+INDEX(Kernels!$B$5:$D$7,2,1)*INDEX(Datos!$B$3:$K$12,($A23+1)+0,(D$15+1)+-1)+INDEX(Kernels!$B$5:$D$7,2,2)*INDEX(Datos!$B$3:$K$12,($A23+1)+0,(D$15+1)+0)+INDEX(Kernels!$B$5:$D$7,2,3)*INDEX(Datos!$B$3:$K$12,($A23+1)+0,(D$15+1)+1)+INDEX(Kernels!$B$5:$D$7,3,1)*INDEX(Datos!$B$3:$K$12,($A23+1)+1,(D$15+1)+-1)+INDEX(Kernels!$B$5:$D$7,3,2)*INDEX(Datos!$B$3:$K$12,($A23+1)+1,(D$15+1)+0)+INDEX(Kernels!$B$5:$D$7,3,3)*INDEX(Datos!$B$3:$K$12,($A23+1)+1,(D$15+1)+1))/Kernels!$F$6,"") -> 80.111111 | E23: =IF(AND($A23>=1,$A23<=8,E$15>=1,E$15<=8),(INDEX(Kernels!$B$5:$D$7,1,1)*INDEX(Datos!$B$3:$K$12,($A23+1)+-1,(E$15+1)+-1)+INDEX(Kernels!$B$5:$D$7,1,2)*INDEX(Datos!$B$3:$K$12,($A23+1)+-1,(E$15+1)+0)+INDEX(Kernels!$B$5:$D$7,1,3)*INDEX(Datos!$B$3:$K$12,($A23+1)+-1,(E$15+1)+1)+INDEX(Kernels!$B$5:$D$7,2,1)*INDEX(Datos!$B$3:$K$12,($A23+1)+0,(E$15+1)+-1)+INDEX(Kernels!$B$5:$D$7,2,2)*INDEX(Datos!$B$3:$K$12,($A23+1)+0,(E$15+1)+0)+INDEX(Kernels!$B$5:$D$7,2,3)*INDEX(Datos!$B$3:$K$12,($A23+1)+0,(E$15+1)+1)+INDEX(Kernels!$B$5:$D$7,3,1)*INDEX(Datos!$B$3:$K$12,($A23+1)+1,(E$15+1)+-1)+INDEX(Kernels!$B$5:$D$7,3,2)*INDEX(Datos!$B$3:$K$12,($A23+1)+1,(E$15+1)+0)+INDEX(Kernels!$B$5:$D$7,3,3)*INDEX(Datos!$B$3:$K$12,($A23+1)+1,(E$15+1)+1))/Kernels!$F$6,"") -> 96.666667 | F23: =IF(AND($A23>=1,$A23<=8,F$15>=1,F$15<=8),(INDEX(Kernels!$B$5:$D$7,1,1)*INDEX(Datos!$B$3:$K$12,($A23+1)+-1,(F$15+1)+-1)+INDEX(Kernels!$B$5:$D$7,1,2)*INDEX(Datos!$B$3:$K$12,($A23+1)+-1,(F$15+1)+0)+INDEX(Kernels!$B$5:$D$7,1,3)*INDEX(Datos!$B$3:$K$12,($A23+1)+-1,(F$15+1)+1)+INDEX(Kernels!$B$5:$D$7,2,1)*INDEX(Datos!$B$3:$K$12,($A23+1)+0,(F$15+1)+-1)+INDEX(Kernels!$B$5:$D$7,2,2)*INDEX(Datos!$B$3:$K$12,($A23+1)+0,(F$15+1)+0)+INDEX(Kernels!$B$5:$D$7,2,3)*INDEX(Datos!$B$3:$K$12,($A23+1)+0,(F$15+1)+1)+INDEX(Kernels!$B$5:$D$7,3,1)*INDEX(Datos!$B$3:$K$12,($A23+1)+1,(F$15+1)+-1)+INDEX(Kernels!$B$5:$D$7,3,2)*INDEX(Datos!$B$3:$K$12,($A23+1)+1,(F$15+1)+0)+INDEX(Kernels!$B$5:$D$7,3,3)*INDEX(Datos!$B$3:$K$12,($A23+1)+1,(F$15+1)+1))/Kernels!$F$6,"") -> 107.44444 | G23: =IF(AND($A23>=1,$A23<=8,G$15>=1,G$15<=8),(INDEX(Kernels!$B$5:$D$7,1,1)*INDEX(Datos!$B$3:$K$12,($A23+1)+-1,(G$15+1)+-1)+INDEX(Kernels!$B$5:$D$7,1,2)*INDEX(Datos!$B$3:$K$12,($A23+1)+-1,(G$15+1)+0)+INDEX(Kernels!$B$5:$D$7,1,3)*INDEX(Datos!$B$3:$K$12,($A23+1)+-1,(G$15+1)+1)+INDEX(Kernels!$B$5:$D$7,2,1)*INDEX(Datos!$B$3:$K$12,($A23+1)+0,(G$15+1)+-1)+INDEX(Kernels!$B$5:$D$7,2,2)*INDEX(Datos!$B$3:$K$12,($A23+1)+0,(G$15+1)+0)+INDEX(Kernels!$B$5:$D$7,2,3)*INDEX(Datos!$B$3:$K$12,($A23+1)+0,(G$15+1)+1)+INDEX(Kernels!$B$5:$D$7,3,1)*INDEX(Datos!$B$3:$K$12,($A23+1)+1,(G$15+1)+-1)+INDEX(Kernels!$B$5:$D$7,3,2)*INDEX(Datos!$B$3:$K$12,($A23+1)+1,(G$15+1)+0)+INDEX(Kernels!$B$5:$D$7,3,3)*INDEX(Datos!$B$3:$K$12,($A23+1)+1,(G$15+1)+1))/Kernels!$F$6,"") -> 111.88889 | H23: =IF(AND($A23>=1,$A23<=8,H$15>=1,H$15<=8),(INDEX(Kernels!$B$5:$D$7,1,1)*INDEX(Datos!$B$3:$K$12,($A23+1)+-1,(H$15+1)+-1)+INDEX(Kernels!$B$5:$D$7,1,2)*INDEX(Datos!$B$3:$K$12,($A23+1)+-1,(H$15+1)+0)+INDEX(Kernels!$B$5:$D$7,1,3)*INDEX(Datos!$B$3:$K$12,($A23+1)+-1,(H$15+1)+1)+INDEX(Kernels!$B$5:$D$7,2,1)*INDEX(Datos!$B$3:$K$12,($A23+1)+0,(H$15+1)+-1)+INDEX(Kernels!$B$5:$D$7,2,2)*INDEX(Datos!$B$3:$K$12,($A23+1)+0,(H$15+1)+0)+INDEX(Kernels!$B$5:$D$7,2,3)*INDEX(Datos!$B$3:$K$12,($A23+1)+0,(H$15+1)+1)+INDEX(Kernels!$B$5:$D$7,3,1)*INDEX(Datos!$B$3:$K$12,($A23+1)+1,(H$15+1)+-1)+INDEX(Kernels!$B$5:$D$7,3,2)*INDEX(Datos!$B$3:$K$12,($A23+1)+1,(H$15+1)+0)+INDEX(Kernels!$B$5:$D$7,3,3)*INDEX(Datos!$B$3:$K$12,($A23+1)+1,(H$15+1)+1))/Kernels!$F$6,"") -> 120.22222 | I23: =IF(AND($A23>=1,$A23<=8,I$15>=1,I$15<=8),(INDEX(Kernels!$B$5:$D$7,1,1)*INDEX(Datos!$B$3:$K$12,($A23+1)+-1,(I$15+1)+-1)+INDEX(Kernels!$B$5:$D$7,1,2)*INDEX(Datos!$B$3:$K$12,($A23+1)+-1,(I$15+1)+0)+INDEX(Kernels!$B$5:$D$7,1,3)*INDEX(Datos!$B$3:$K$12,($A23+1)+-1,(I$15+1)+1)+INDEX(Kernels!$B$5:$D$7,2,1)*INDEX(Datos!$B$3:$K$12,($A23+1)+0,(I$15+1)+-1)+INDEX(Kernels!$B$5:$D$7,2,2)*INDEX(Datos!$B$3:$K$12,($A23+1)+0,(I$15+1)+0)+INDEX(Kernels!$B$5:$D$7,2,3)*INDEX(Datos!$B$3:$K$12,($A23+1)+0,(I$15+1)+1)+INDEX(Kernels!$B$5:$D$7,3,1)*INDEX(Datos!$B$3:$K$12,($A23+1)+1,(I$15+1)+-1)+INDEX(Kernels!$B$5:$D$7,3,2)*INDEX(Datos!$B$3:$K$12,($A23+1)+1,(I$15+1)+0)+INDEX(Kernels!$B$5:$D$7,3,3)*INDEX(Datos!$B$3:$K$12,($A23+1)+1,(I$15+1)+1))/Kernels!$F$6,"") -> 129 | ... K23: =IF(AND($A23>=1,$A23<=8,K$15>=1,K$15<=8),(INDEX(Kernels!$B$5:$D$7,1,1)*INDEX(Datos!$B$3:$K$12,($A23+1)+-1,(K$15+1)+-1)+INDEX(Kernels!$B$5:$D$7,1,2)*INDEX(Datos!$B$3:$K$12,($A23+1)+-1,(K$15+1)+0)+INDEX(Kernels!$B$5:$D$7,1,3)*INDEX(Datos!$B$3:$K$12,($A23+1)+-1,(K$15+1)+1)+INDEX(Kernels!$B$5:$D$7,2,1)*INDEX(Datos!$B$3:$K$12,($A23+1)+0,(K$15+1)+-1)+INDEX(Kernels!$B$5:$D$7,2,2)*INDEX(Datos!$B$3:$K$12,($A23+1)+0,(K$15+1)+0)+INDEX(Kernels!$B$5:$D$7,2,3)*INDEX(Datos!$B$3:$K$12,($A23+1)+0,(K$15+1)+1)+INDEX(Kernels!$B$5:$D$7,3,1)*INDEX(Datos!$B$3:$K$12,($A23+1)+1,(K$15+1)+-1)+INDEX(Kernels!$B$5:$D$7,3,2)*INDEX(Datos!$B$3:$K$12,($A23+1)+1,(K$15+1)+0)+INDEX(Kernels!$B$5:$D$7,3,3)*INDEX(Datos!$B$3:$K$12,($A23+1)+1,(K$15+1)+1))/Kernels!$F$6,"")
